<robot name = "robot">
    <link name="link1">
        <inertial>
            <origin xyz="1.2402410986822394 0 0" rpy="0 0 0"/>
            <mass value="3.9827217711169247" />
            <inertia ixx="100" ixy="0" ixz="0" iyy="100" iyz="0" izz="100" />
        </inertial>
        <visual>
            <origin xyz="1.2402410986822394 0 0" rpy="0 0 0"/>
            <geometry>
                <box size="2.480482197364479 1.546238724828834 1.7471366388772473" />
            </geometry>
            <material name="Blue">
                <color rgba="0 0 1 1"/>
            </material>
        </visual>
        <collision>
            <origin xyz="1.2402410986822394 0 0" rpy="0 0 0"/>
            <geometry>
                <box size="2.480482197364479 1.546238724828834 1.7471366388772473" />
            </geometry>
        </collision>
    </link>
    <joint name="link1_link2" type="revolute">
       <parent link="link1"/>
       <child  link="link2"/>
       <origin rpy="0 0 0" xyz="2.480482197364479 0 0" />
       <axis xyz="0 1 0"/>
       <limit effort="0.0" lower="-3.14159" upper="3.14159" velocity="0.0"/>
    </joint>
    <link name="link2">
        <inertial>
            <origin xyz="0.7643775270830703 0 0" rpy="0 0 0"/>
            <mass value="1.4231030627284031" />
            <inertia ixx="100" ixy="0" ixz="0" iyy="100" iyz="0" izz="100" />
        </inertial>
        <visual>
            <origin xyz="0.7643775270830703 0 0" rpy="0 0 0"/>
            <geometry>
                <box size="1.5287550541661405 1.3892062341850329 0.8458872123420884" />
            </geometry>
            <material name="Blue">
                <color rgba="0 0 1 1"/>
            </material>
        </visual>
        <collision>
            <origin xyz="0.7643775270830703 0 0" rpy="0 0 0"/>
            <geometry>
                <box size="1.5287550541661405 1.3892062341850329 0.8458872123420884" />
            </geometry>
        </collision>
    </link>
    <joint name="link2_link3" type="revolute">
       <parent link="link2"/>
       <child  link="link3"/>
       <origin rpy="0 0 0" xyz="1.5287550541661405 0 0" />
       <axis xyz="0 1 0"/>
       <limit effort="0.0" lower="-3.14159" upper="3.14159" velocity="0.0"/>
    </joint>
    <link name="link3">
        <inertial>
            <origin xyz="0.5915248675472308 0 0" rpy="0 0 0"/>
            <mass value="0.21214268213914422" />
            <inertia ixx="100" ixy="0" ixz="0" iyy="100" iyz="0" izz="100" />
        </inertial>
        <visual>
            <origin xyz="0.5915248675472308 0 0" rpy="0 0 0"/>
            <geometry>
                <box size="1.1830497350944615 1.8214631775665986 1.1667967831755843" />
            </geometry>
            <material name="Blue">
                <color rgba="0 0 1 1"/>
            </material>
        </visual>
        <collision>
            <origin xyz="0.5915248675472308 0 0" rpy="0 0 0"/>
            <geometry>
                <box size="1.1830497350944615 1.8214631775665986 1.1667967831755843" />
            </geometry>
        </collision>
    </link>
    <joint name="link3_link4" type="revolute">
       <parent link="link3"/>
       <child  link="link4"/>
       <origin rpy="0 0 0" xyz="1.1830497350944615 0 0" />
       <axis xyz="0 1 0"/>
       <limit effort="0.0" lower="-3.14159" upper="3.14159" velocity="0.0"/>
    </joint>
    <link name="link4">
        <inertial>
            <origin xyz="0.8386607879022151 0 0" rpy="0 0 0"/>
            <mass value="3.841650219171873" />
            <inertia ixx="100" ixy="0" ixz="0" iyy="100" iyz="0" izz="100" />
        </inertial>
        <visual>
            <origin xyz="0.8386607879022151 0 0" rpy="0 0 0"/>
            <geometry>
                <box size="1.6773215758044302 0.7319319430486682 1.4578258166921434" />
            </geometry>
            <material name="Blue">
                <color rgba="0 0 1 1"/>
            </material>
        </visual>
        <collision>
            <origin xyz="0.8386607879022151 0 0" rpy="0 0 0"/>
            <geometry>
                <box size="1.6773215758044302 0.7319319430486682 1.4578258166921434" />
            </geometry>
        </collision>
    </link>
    <joint name="link4_link5" type="revolute">
       <parent link="link4"/>
       <child  link="link5"/>
       <origin rpy="0 0 0" xyz="1.6773215758044302 0 0" />
       <axis xyz="0 1 0"/>
       <limit effort="0.0" lower="-3.14159" upper="3.14159" velocity="0.0"/>
    </joint>
    <link name="link5">
        <inertial>
            <origin xyz="1.0486574343215374 0 0" rpy="0 0 0"/>
            <mass value="2.959809148669404" />
            <inertia ixx="100" ixy="0" ixz="0" iyy="100" iyz="0" izz="100" />
        </inertial>
        <visual>
            <origin xyz="1.0486574343215374 0 0" rpy="0 0 0"/>
            <geometry>
                <box size="2.0973148686430747 1.436787657902716 1.4990529832392652" />
            </geometry>
            <material name="Green">
                <color rgba="0 1 0 1"/>
            </material>
        </visual>
        <collision>
            <origin xyz="1.0486574343215374 0 0" rpy="0 0 0"/>
            <geometry>
                <box size="2.0973148686430747 1.436787657902716 1.4990529832392652" />
            </geometry>
        </collision>
    </link>
    <joint name="link5_link6" type="revolute">
       <parent link="link5"/>
       <child  link="link6"/>
       <origin rpy="0 0 0" xyz="2.0973148686430747 0 0" />
       <axis xyz="0 1 0"/>
       <limit effort="0.0" lower="-3.14159" upper="3.14159" velocity="0.0"/>
    </joint>
    <link name="link6">
        <inertial>
            <origin xyz="0.8478239572810903 0 0" rpy="0 0 0"/>
            <mass value="2.8098439176359347" />
            <inertia ixx="100" ixy="0" ixz="0" iyy="100" iyz="0" izz="100" />
        </inertial>
        <visual>
            <origin xyz="0.8478239572810903 0 0" rpy="0 0 0"/>
            <geometry>
                <box size="1.6956479145621806 0.6681695716716749 1.9842321586406029" />
            </geometry>
            <material name="Green">
                <color rgba="0 1 0 1"/>
            </material>
        </visual>
        <collision>
            <origin xyz="0.8478239572810903 0 0" rpy="0 0 0"/>
            <geometry>
                <box size="1.6956479145621806 0.6681695716716749 1.9842321586406029" />
            </geometry>
        </collision>
    </link>
    <joint name="link6_link7" type="revolute">
       <parent link="link6"/>
       <child  link="link7"/>
       <origin rpy="0 0 0" xyz="1.6956479145621806 0 0" />
       <axis xyz="0 1 0"/>
       <limit effort="0.0" lower="-3.14159" upper="3.14159" velocity="0.0"/>
    </joint>
    <link name="link7">
        <inertial>
            <origin xyz="0.9198360827068695 0 0" rpy="0 0 0"/>
            <mass value="2.165015299481659" />
            <inertia ixx="100" ixy="0" ixz="0" iyy="100" iyz="0" izz="100" />
        </inertial>
        <visual>
            <origin xyz="0.9198360827068695 0 0" rpy="0 0 0"/>
            <geometry>
                <box size="1.839672165413739 1.7404081688742785 1.7654005992101984" />
            </geometry>
            <material name="Blue">
                <color rgba="0 0 1 1"/>
            </material>
        </visual>
        <collision>
            <origin xyz="0.9198360827068695 0 0" rpy="0 0 0"/>
            <geometry>
                <box size="1.839672165413739 1.7404081688742785 1.7654005992101984" />
            </geometry>
        </collision>
    </link>
    <joint name="link7_link8" type="revolute">
       <parent link="link7"/>
       <child  link="link8"/>
       <origin rpy="0 0 0" xyz="1.839672165413739 0 0" />
       <axis xyz="0 1 0"/>
       <limit effort="0.0" lower="-3.14159" upper="3.14159" velocity="0.0"/>
    </joint>
    <link name="link8">
        <inertial>
            <origin xyz="0.9198360827068695 0 0" rpy="0 0 0"/>
            <mass value="2.282844774048807" />
            <inertia ixx="100" ixy="0" ixz="0" iyy="100" iyz="0" izz="100" />
        </inertial>
        <visual>
            <origin xyz="0.9198360827068695 0 0" rpy="0 0 0"/>
            <geometry>
                <box size="1.839672165413739 1.8034821462811303 1.9398527363323463" />
            </geometry>
            <material name="Blue">
                <color rgba="0 0 1 1"/>
            </material>
        </visual>
        <collision>
            <origin xyz="0.9198360827068695 0 0" rpy="0 0 0"/>
            <geometry>
                <box size="1.839672165413739 1.8034821462811303 1.9398527363323463" />
            </geometry>
        </collision>
    </link>
</robot>