<robot name = "robot">
    <link name="rootLink">
        <inertial>
            <origin xyz="0 0 1" rpy="0 0 0"/>
            <mass value="10" />
            <inertia ixx="100" ixy="0" ixz="0" iyy="100" iyz="0" izz="100" />
        </inertial>
        <visual>
            <origin xyz="0 0 1" rpy="0 0 0"/>
            <geometry>
                <box size="1 1 1" />
            </geometry>
            <material name="Green">
                <color rgba="0 1 0 1"/>
            </material>
        </visual>
        <collision>
            <origin xyz="0 0 1" rpy="0 0 0"/>
            <geometry>
                <box size="1 1 1" />
            </geometry>
        </collision>
    </link>
    <joint name="rootLink_link1NPP" type="revolute">
       <parent link="rootLink"/>
       <child  link="link1NPP"/>
       <origin rpy="0 0 0" xyz="0 0.5 0.5" />
       <axis xyz="0 1 0"/>
       <limit effort="0.0" lower="-3.14159" upper="3.14159" velocity="0.0"/>
    </joint>
    <joint name="rootLink_link1NNP" type="revolute">
       <parent link="rootLink"/>
       <child  link="link1NNP"/>
       <origin rpy="0 0 0" xyz="0 -0.5 0.5" />
       <axis xyz="0 1 0"/>
       <limit effort="0.0" lower="-3.14159" upper="3.14159" velocity="0.0"/>
    </joint>
    <link name="link1NPP">
        <inertial>
            <origin xyz="0 1 1" rpy="0 0 0"/>
            <mass value="1" />
            <inertia ixx="100" ixy="0" ixz="0" iyy="100" iyz="0" izz="100" />
        </inertial>
        <visual>
            <origin xyz="0 1 1" rpy="0 0 0"/>
            <geometry>
                <box size="0 0 1" />
            </geometry>
            <material name="Blue">
                <color rgba="0 0 1 1"/>
            </material>
        </visual>
        <collision>
            <origin xyz="0 1 1" rpy="0 0 0"/>
            <geometry>
                <box size="0 0 1" />
            </geometry>
        </collision>
    </link>
    <link name="link2NPP">
        <inertial>
            <origin xyz="-0.1048184261426579 0 0" rpy="0 0 0"/>
            <mass value="1" />
            <inertia ixx="100" ixy="0" ixz="0" iyy="100" iyz="0" izz="100" />
        </inertial>
        <visual>
            <origin xyz="-0.1048184261426579 0 0" rpy="0 0 0"/>
            <geometry>
                <box size="0.2096368522853158 0.5654848559859877 0.5701950169606016" />
            </geometry>
            <material name="Blue">
                <color rgba="0 0 1 1"/>
            </material>
        </visual>
        <collision>
            <origin xyz="-0.1048184261426579 0 0" rpy="0 0 0"/>
            <geometry>
                <box size="0.2096368522853158 0.5654848559859877 0.5701950169606016" />
            </geometry>
        </collision>
    </link>
    <link name="link3NPP">
        <inertial>
            <origin xyz="0 0 0.40168062654151215" rpy="0 0 0"/>
            <mass value="1" />
            <inertia ixx="100" ixy="0" ixz="0" iyy="100" iyz="0" izz="100" />
        </inertial>
        <visual>
            <origin xyz="0 0 0.40168062654151215" rpy="0 0 0"/>
            <geometry>
                <box size="0.5509384984747858 0.42437023576917177 0.8033612530830243" />
            </geometry>
            <material name="Green">
                <color rgba="0 1 0 1"/>
            </material>
        </visual>
        <collision>
            <origin xyz="0 0 0.40168062654151215" rpy="0 0 0"/>
            <geometry>
                <box size="0.5509384984747858 0.42437023576917177 0.8033612530830243" />
            </geometry>
        </collision>
    </link>
    <link name="link4NPP">
        <inertial>
            <origin xyz="0 0.2797537106895355 0" rpy="0 0 0"/>
            <mass value="1" />
            <inertia ixx="100" ixy="0" ixz="0" iyy="100" iyz="0" izz="100" />
        </inertial>
        <visual>
            <origin xyz="0 0.2797537106895355 0" rpy="0 0 0"/>
            <geometry>
                <box size="0.8312712463921201 0.559507421379071 0.518589386631407" />
            </geometry>
            <material name="Green">
                <color rgba="0 1 0 1"/>
            </material>
        </visual>
        <collision>
            <origin xyz="0 0.2797537106895355 0" rpy="0 0 0"/>
            <geometry>
                <box size="0.8312712463921201 0.559507421379071 0.518589386631407" />
            </geometry>
        </collision>
    </link>
    <link name="link5NPP">
        <inertial>
            <origin xyz="0 0 0.42566125838318547" rpy="0 0 0"/>
            <mass value="1" />
            <inertia ixx="100" ixy="0" ixz="0" iyy="100" iyz="0" izz="100" />
        </inertial>
        <visual>
            <origin xyz="0 0 0.42566125838318547" rpy="0 0 0"/>
            <geometry>
                <box size="0.4115067271500367 0.31856623679810997 0.8513225167663709" />
            </geometry>
            <material name="Blue">
                <color rgba="0 0 1 1"/>
            </material>
        </visual>
        <collision>
            <origin xyz="0 0 0.42566125838318547" rpy="0 0 0"/>
            <geometry>
                <box size="0.4115067271500367 0.31856623679810997 0.8513225167663709" />
            </geometry>
        </collision>
    </link>
    <link name="link1NNP">
        <inertial>
            <origin xyz="0 1 1" rpy="0 0 0"/>
            <mass value="1" />
            <inertia ixx="100" ixy="0" ixz="0" iyy="100" iyz="0" izz="100" />
        </inertial>
        <visual>
            <origin xyz="0 1 1" rpy="0 0 0"/>
            <geometry>
                <box size="0 0 1" />
            </geometry>
            <material name="Blue">
                <color rgba="0 0 1 1"/>
            </material>
        </visual>
        <collision>
            <origin xyz="0 1 1" rpy="0 0 0"/>
            <geometry>
                <box size="0 0 1" />
            </geometry>
        </collision>
    </link>
    <link name="link2NNP">
        <inertial>
            <origin xyz="-0.1048184261426579 0 0" rpy="0 0 0"/>
            <mass value="1" />
            <inertia ixx="100" ixy="0" ixz="0" iyy="100" iyz="0" izz="100" />
        </inertial>
        <visual>
            <origin xyz="-0.1048184261426579 0 0" rpy="0 0 0"/>
            <geometry>
                <box size="0.2096368522853158 0.5654848559859877 0.5701950169606016" />
            </geometry>
            <material name="Blue">
                <color rgba="0 0 1 1"/>
            </material>
        </visual>
        <collision>
            <origin xyz="-0.1048184261426579 0 0" rpy="0 0 0"/>
            <geometry>
                <box size="0.2096368522853158 0.5654848559859877 0.5701950169606016" />
            </geometry>
        </collision>
    </link>
    <link name="link3NNP">
        <inertial>
            <origin xyz="0 0 0.40168062654151215" rpy="0 0 0"/>
            <mass value="1" />
            <inertia ixx="100" ixy="0" ixz="0" iyy="100" iyz="0" izz="100" />
        </inertial>
        <visual>
            <origin xyz="0 0 0.40168062654151215" rpy="0 0 0"/>
            <geometry>
                <box size="0.5509384984747858 0.42437023576917177 0.8033612530830243" />
            </geometry>
            <material name="Green">
                <color rgba="0 1 0 1"/>
            </material>
        </visual>
        <collision>
            <origin xyz="0 0 0.40168062654151215" rpy="0 0 0"/>
            <geometry>
                <box size="0.5509384984747858 0.42437023576917177 0.8033612530830243" />
            </geometry>
        </collision>
    </link>
    <link name="link4NNP">
        <inertial>
            <origin xyz="0 -0.2797537106895355 0" rpy="0 0 0"/>
            <mass value="1" />
            <inertia ixx="100" ixy="0" ixz="0" iyy="100" iyz="0" izz="100" />
        </inertial>
        <visual>
            <origin xyz="0 -0.2797537106895355 0" rpy="0 0 0"/>
            <geometry>
                <box size="0.8312712463921201 0.559507421379071 0.518589386631407" />
            </geometry>
            <material name="Green">
                <color rgba="0 1 0 1"/>
            </material>
        </visual>
        <collision>
            <origin xyz="0 -0.2797537106895355 0" rpy="0 0 0"/>
            <geometry>
                <box size="0.8312712463921201 0.559507421379071 0.518589386631407" />
            </geometry>
        </collision>
    </link>
    <link name="link5NNP">
        <inertial>
            <origin xyz="0 0 0.42566125838318547" rpy="0 0 0"/>
            <mass value="1" />
            <inertia ixx="100" ixy="0" ixz="0" iyy="100" iyz="0" izz="100" />
        </inertial>
        <visual>
            <origin xyz="0 0 0.42566125838318547" rpy="0 0 0"/>
            <geometry>
                <box size="0.4115067271500367 0.31856623679810997 0.8513225167663709" />
            </geometry>
            <material name="Blue">
                <color rgba="0 0 1 1"/>
            </material>
        </visual>
        <collision>
            <origin xyz="0 0 0.42566125838318547" rpy="0 0 0"/>
            <geometry>
                <box size="0.4115067271500367 0.31856623679810997 0.8513225167663709" />
            </geometry>
        </collision>
    </link>
    <joint name="link1NPP_link2NPP" type="revolute">
       <parent link="link1NPP"/>
       <child  link="link2NPP"/>
       <origin rpy="0 0 0" xyz="0.0 0 0.5" />
       <axis xyz="0 1 0"/>
       <limit effort="0.0" lower="-3.14159" upper="3.14159" velocity="0.0"/>
    </joint>
    <joint name="link2NPP_link3NPP" type="revolute">
       <parent link="link2NPP"/>
       <child  link="link3NPP"/>
       <origin rpy="0 0 0" xyz="-0.1048184261426579 0 0.2850975084803008" />
       <axis xyz="0 1 0"/>
       <limit effort="0.0" lower="-3.14159" upper="3.14159" velocity="0.0"/>
    </joint>
    <joint name="link3NPP_link4NPP" type="revolute">
       <parent link="link3NPP"/>
       <child  link="link4NPP"/>
       <origin rpy="0 0 0" xyz="0 0.21218511788458588 0.40168062654151215" />
       <axis xyz="0 1 0"/>
       <limit effort="0.0" lower="-3.14159" upper="3.14159" velocity="0.0"/>
    </joint>
    <joint name="link4NPP_link5NPP" type="revolute">
       <parent link="link4NPP"/>
       <child  link="link5NPP"/>
       <origin rpy="0 0 0" xyz="0 0.2797537106895355 0.2592946933157035" />
       <axis xyz="0 1 0"/>
       <limit effort="0.0" lower="-3.14159" upper="3.14159" velocity="0.0"/>
    </joint>
    <joint name="link1NNP_link2NNP" type="revolute">
       <parent link="link1NNP"/>
       <child  link="link2NNP"/>
       <origin rpy="0 0 0" xyz="0.0 0 0.5" />
       <axis xyz="0 1 0"/>
       <limit effort="0.0" lower="-3.14159" upper="3.14159" velocity="0.0"/>
    </joint>
    <joint name="link2NNP_link3NNP" type="revolute">
       <parent link="link2NNP"/>
       <child  link="link3NNP"/>
       <origin rpy="0 0 0" xyz="-0.1048184261426579 0 0.2850975084803008" />
       <axis xyz="0 1 0"/>
       <limit effort="0.0" lower="-3.14159" upper="3.14159" velocity="0.0"/>
    </joint>
    <joint name="link3NNP_link4NNP" type="revolute">
       <parent link="link3NNP"/>
       <child  link="link4NNP"/>
       <origin rpy="0 0 0" xyz="0 -0.21218511788458588 0.40168062654151215" />
       <axis xyz="0 1 0"/>
       <limit effort="0.0" lower="-3.14159" upper="3.14159" velocity="0.0"/>
    </joint>
    <joint name="link4NNP_link5NNP" type="revolute">
       <parent link="link4NNP"/>
       <child  link="link5NNP"/>
       <origin rpy="0 0 0" xyz="0 -0.2797537106895355 0.2592946933157035" />
       <axis xyz="0 1 0"/>
       <limit effort="0.0" lower="-3.14159" upper="3.14159" velocity="0.0"/>
    </joint>
</robot>