<robot name = "robot">
    <link name="rootLink">
        <inertial>
            <origin xyz="0 0 1" rpy="0 0 0"/>
            <mass value="10" />
            <inertia ixx="100" ixy="0" ixz="0" iyy="100" iyz="0" izz="100" />
        </inertial>
        <visual>
            <origin xyz="0 0 1" rpy="0 0 0"/>
            <geometry>
                <box size="1 1 1" />
            </geometry>
            <material name="Green">
                <color rgba="0 1 0 1"/>
            </material>
        </visual>
        <collision>
            <origin xyz="0 0 1" rpy="0 0 0"/>
            <geometry>
                <box size="1 1 1" />
            </geometry>
        </collision>
    </link>
    <joint name="rootLink_link1NPP" type="revolute">
       <parent link="rootLink"/>
       <child  link="link1NPP"/>
       <origin rpy="0 0 0" xyz="0 0.5 0.5" />
       <axis xyz="0 1 0"/>
       <limit effort="0.0" lower="-3.14159" upper="3.14159" velocity="0.0"/>
    </joint>
    <joint name="rootLink_link1NNP" type="revolute">
       <parent link="rootLink"/>
       <child  link="link1NNP"/>
       <origin rpy="0 0 0" xyz="0 -0.5 0.5" />
       <axis xyz="0 1 0"/>
       <limit effort="0.0" lower="-3.14159" upper="3.14159" velocity="0.0"/>
    </joint>
    <link name="link1NPP">
        <inertial>
            <origin xyz="0 1 1" rpy="0 0 0"/>
            <mass value="1" />
            <inertia ixx="100" ixy="0" ixz="0" iyy="100" iyz="0" izz="100" />
        </inertial>
        <visual>
            <origin xyz="0 1 1" rpy="0 0 0"/>
            <geometry>
                <box size="0 0 1" />
            </geometry>
            <material name="Green">
                <color rgba="0 1 0 1"/>
            </material>
        </visual>
        <collision>
            <origin xyz="0 1 1" rpy="0 0 0"/>
            <geometry>
                <box size="0 0 1" />
            </geometry>
        </collision>
    </link>
    <link name="link2NPP">
        <inertial>
            <origin xyz="0 0.29209895486477533 0" rpy="0 0 0"/>
            <mass value="1" />
            <inertia ixx="100" ixy="0" ixz="0" iyy="100" iyz="0" izz="100" />
        </inertial>
        <visual>
            <origin xyz="0 0.29209895486477533 0" rpy="0 0 0"/>
            <geometry>
                <box size="0.8453526216949434 0.5841979097295507 0.4317003022115724" />
            </geometry>
            <material name="Green">
                <color rgba="0 1 0 1"/>
            </material>
        </visual>
        <collision>
            <origin xyz="0 0.29209895486477533 0" rpy="0 0 0"/>
            <geometry>
                <box size="0.8453526216949434 0.5841979097295507 0.4317003022115724" />
            </geometry>
        </collision>
    </link>
    <link name="link3NPP">
        <inertial>
            <origin xyz="-0.14406481956688474 0 0" rpy="0 0 0"/>
            <mass value="1" />
            <inertia ixx="100" ixy="0" ixz="0" iyy="100" iyz="0" izz="100" />
        </inertial>
        <visual>
            <origin xyz="-0.14406481956688474 0 0" rpy="0 0 0"/>
            <geometry>
                <box size="0.2881296391337695 0.21077471151621074 0.5073368836354379" />
            </geometry>
            <material name="Green">
                <color rgba="0 1 0 1"/>
            </material>
        </visual>
        <collision>
            <origin xyz="-0.14406481956688474 0 0" rpy="0 0 0"/>
            <geometry>
                <box size="0.2881296391337695 0.21077471151621074 0.5073368836354379" />
            </geometry>
        </collision>
    </link>
    <link name="link4NPP">
        <inertial>
            <origin xyz="0 0 0.2269740362182999" rpy="0 0 0"/>
            <mass value="1" />
            <inertia ixx="100" ixy="0" ixz="0" iyy="100" iyz="0" izz="100" />
        </inertial>
        <visual>
            <origin xyz="0 0 0.2269740362182999" rpy="0 0 0"/>
            <geometry>
                <box size="0.4019070140105776 0.40064106822721346 0.4539480724365998" />
            </geometry>
            <material name="Blue">
                <color rgba="0 0 1 1"/>
            </material>
        </visual>
        <collision>
            <origin xyz="0 0 0.2269740362182999" rpy="0 0 0"/>
            <geometry>
                <box size="0.4019070140105776 0.40064106822721346 0.4539480724365998" />
            </geometry>
        </collision>
    </link>
    <link name="link5NPP">
        <inertial>
            <origin xyz="0 0.2102368817660105 0" rpy="0 0 0"/>
            <mass value="1" />
            <inertia ixx="100" ixy="0" ixz="0" iyy="100" iyz="0" izz="100" />
        </inertial>
        <visual>
            <origin xyz="0 0.2102368817660105 0" rpy="0 0 0"/>
            <geometry>
                <box size="0.3100331306364954 0.420473763532021 0.3119053471839964" />
            </geometry>
            <material name="Blue">
                <color rgba="0 0 1 1"/>
            </material>
        </visual>
        <collision>
            <origin xyz="0 0.2102368817660105 0" rpy="0 0 0"/>
            <geometry>
                <box size="0.3100331306364954 0.420473763532021 0.3119053471839964" />
            </geometry>
        </collision>
    </link>
    <link name="link6NPP">
        <inertial>
            <origin xyz="-0.39785870692879854 0 0" rpy="0 0 0"/>
            <mass value="1" />
            <inertia ixx="100" ixy="0" ixz="0" iyy="100" iyz="0" izz="100" />
        </inertial>
        <visual>
            <origin xyz="-0.39785870692879854 0 0" rpy="0 0 0"/>
            <geometry>
                <box size="0.7957174138575971 0.38952442894310346 0.24316475825896547" />
            </geometry>
            <material name="Green">
                <color rgba="0 1 0 1"/>
            </material>
        </visual>
        <collision>
            <origin xyz="-0.39785870692879854 0 0" rpy="0 0 0"/>
            <geometry>
                <box size="0.7957174138575971 0.38952442894310346 0.24316475825896547" />
            </geometry>
        </collision>
    </link>
    <link name="link1NNP">
        <inertial>
            <origin xyz="0 1 1" rpy="0 0 0"/>
            <mass value="1" />
            <inertia ixx="100" ixy="0" ixz="0" iyy="100" iyz="0" izz="100" />
        </inertial>
        <visual>
            <origin xyz="0 1 1" rpy="0 0 0"/>
            <geometry>
                <box size="0 0 1" />
            </geometry>
            <material name="Green">
                <color rgba="0 1 0 1"/>
            </material>
        </visual>
        <collision>
            <origin xyz="0 1 1" rpy="0 0 0"/>
            <geometry>
                <box size="0 0 1" />
            </geometry>
        </collision>
    </link>
    <link name="link2NNP">
        <inertial>
            <origin xyz="0 -0.29209895486477533 0" rpy="0 0 0"/>
            <mass value="1" />
            <inertia ixx="100" ixy="0" ixz="0" iyy="100" iyz="0" izz="100" />
        </inertial>
        <visual>
            <origin xyz="0 -0.29209895486477533 0" rpy="0 0 0"/>
            <geometry>
                <box size="0.8453526216949434 0.5841979097295507 0.4317003022115724" />
            </geometry>
            <material name="Green">
                <color rgba="0 1 0 1"/>
            </material>
        </visual>
        <collision>
            <origin xyz="0 -0.29209895486477533 0" rpy="0 0 0"/>
            <geometry>
                <box size="0.8453526216949434 0.5841979097295507 0.4317003022115724" />
            </geometry>
        </collision>
    </link>
    <link name="link3NNP">
        <inertial>
            <origin xyz="-0.14406481956688474 0 0" rpy="0 0 0"/>
            <mass value="1" />
            <inertia ixx="100" ixy="0" ixz="0" iyy="100" iyz="0" izz="100" />
        </inertial>
        <visual>
            <origin xyz="-0.14406481956688474 0 0" rpy="0 0 0"/>
            <geometry>
                <box size="0.2881296391337695 0.21077471151621074 0.5073368836354379" />
            </geometry>
            <material name="Green">
                <color rgba="0 1 0 1"/>
            </material>
        </visual>
        <collision>
            <origin xyz="-0.14406481956688474 0 0" rpy="0 0 0"/>
            <geometry>
                <box size="0.2881296391337695 0.21077471151621074 0.5073368836354379" />
            </geometry>
        </collision>
    </link>
    <link name="link4NNP">
        <inertial>
            <origin xyz="0 0 0.2269740362182999" rpy="0 0 0"/>
            <mass value="1" />
            <inertia ixx="100" ixy="0" ixz="0" iyy="100" iyz="0" izz="100" />
        </inertial>
        <visual>
            <origin xyz="0 0 0.2269740362182999" rpy="0 0 0"/>
            <geometry>
                <box size="0.4019070140105776 0.40064106822721346 0.4539480724365998" />
            </geometry>
            <material name="Blue">
                <color rgba="0 0 1 1"/>
            </material>
        </visual>
        <collision>
            <origin xyz="0 0 0.2269740362182999" rpy="0 0 0"/>
            <geometry>
                <box size="0.4019070140105776 0.40064106822721346 0.4539480724365998" />
            </geometry>
        </collision>
    </link>
    <link name="link5NNP">
        <inertial>
            <origin xyz="0 -0.2102368817660105 0" rpy="0 0 0"/>
            <mass value="1" />
            <inertia ixx="100" ixy="0" ixz="0" iyy="100" iyz="0" izz="100" />
        </inertial>
        <visual>
            <origin xyz="0 -0.2102368817660105 0" rpy="0 0 0"/>
            <geometry>
                <box size="0.3100331306364954 0.420473763532021 0.3119053471839964" />
            </geometry>
            <material name="Blue">
                <color rgba="0 0 1 1"/>
            </material>
        </visual>
        <collision>
            <origin xyz="0 -0.2102368817660105 0" rpy="0 0 0"/>
            <geometry>
                <box size="0.3100331306364954 0.420473763532021 0.3119053471839964" />
            </geometry>
        </collision>
    </link>
    <link name="link6NNP">
        <inertial>
            <origin xyz="-0.39785870692879854 0 0" rpy="0 0 0"/>
            <mass value="1" />
            <inertia ixx="100" ixy="0" ixz="0" iyy="100" iyz="0" izz="100" />
        </inertial>
        <visual>
            <origin xyz="-0.39785870692879854 0 0" rpy="0 0 0"/>
            <geometry>
                <box size="0.7957174138575971 0.38952442894310346 0.24316475825896547" />
            </geometry>
            <material name="Green">
                <color rgba="0 1 0 1"/>
            </material>
        </visual>
        <collision>
            <origin xyz="-0.39785870692879854 0 0" rpy="0 0 0"/>
            <geometry>
                <box size="0.7957174138575971 0.38952442894310346 0.24316475825896547" />
            </geometry>
        </collision>
    </link>
    <joint name="link1NPP_link2NPP" type="revolute">
       <parent link="link1NPP"/>
       <child  link="link2NPP"/>
       <origin rpy="0 0 0" xyz="0 0.0 0.5" />
       <axis xyz="0 1 0"/>
       <limit effort="0.0" lower="-3.14159" upper="3.14159" velocity="0.0"/>
    </joint>
    <joint name="link2NPP_link3NPP" type="revolute">
       <parent link="link2NPP"/>
       <child  link="link3NPP"/>
       <origin rpy="0 0 0" xyz="-0.4226763108474717 0.29209895486477533 0" />
       <axis xyz="0 1 0"/>
       <limit effort="0.0" lower="-3.14159" upper="3.14159" velocity="0.0"/>
    </joint>
    <joint name="link3NPP_link4NPP" type="revolute">
       <parent link="link3NPP"/>
       <child  link="link4NPP"/>
       <origin rpy="0 0 0" xyz="-0.14406481956688474 0 0.25366844181771897" />
       <axis xyz="0 0 1"/>
       <limit effort="0.0" lower="-3.14159" upper="3.14159" velocity="0.0"/>
    </joint>
    <joint name="link4NPP_link5NPP" type="revolute">
       <parent link="link4NPP"/>
       <child  link="link5NPP"/>
       <origin rpy="0 0 0" xyz="0 0.20032053411360673 0.2269740362182999" />
       <axis xyz="0 1 0"/>
       <limit effort="0.0" lower="-3.14159" upper="3.14159" velocity="0.0"/>
    </joint>
    <joint name="link5NPP_link6NPP" type="revolute">
       <parent link="link5NPP"/>
       <child  link="link6NPP"/>
       <origin rpy="0 0 0" xyz="-0.1550165653182477 0.2102368817660105 0" />
       <axis xyz="0 1 0"/>
       <limit effort="0.0" lower="-3.14159" upper="3.14159" velocity="0.0"/>
    </joint>
    <joint name="link1NNP_link2NNP" type="revolute">
       <parent link="link1NNP"/>
       <child  link="link2NNP"/>
       <origin rpy="0 0 0" xyz="0 0.0 0.5" />
       <axis xyz="0 1 0"/>
       <limit effort="0.0" lower="-3.14159" upper="3.14159" velocity="0.0"/>
    </joint>
    <joint name="link2NNP_link3NNP" type="revolute">
       <parent link="link2NNP"/>
       <child  link="link3NNP"/>
       <origin rpy="0 0 0" xyz="-0.4226763108474717 -0.29209895486477533 0" />
       <axis xyz="0 1 0"/>
       <limit effort="0.0" lower="-3.14159" upper="3.14159" velocity="0.0"/>
    </joint>
    <joint name="link3NNP_link4NNP" type="revolute">
       <parent link="link3NNP"/>
       <child  link="link4NNP"/>
       <origin rpy="0 0 0" xyz="-0.14406481956688474 0 0.25366844181771897" />
       <axis xyz="0 0 1"/>
       <limit effort="0.0" lower="-3.14159" upper="3.14159" velocity="0.0"/>
    </joint>
    <joint name="link4NNP_link5NNP" type="revolute">
       <parent link="link4NNP"/>
       <child  link="link5NNP"/>
       <origin rpy="0 0 0" xyz="0 -0.20032053411360673 0.2269740362182999" />
       <axis xyz="0 1 0"/>
       <limit effort="0.0" lower="-3.14159" upper="3.14159" velocity="0.0"/>
    </joint>
    <joint name="link5NNP_link6NNP" type="revolute">
       <parent link="link5NNP"/>
       <child  link="link6NNP"/>
       <origin rpy="0 0 0" xyz="-0.1550165653182477 -0.2102368817660105 0" />
       <axis xyz="0 1 0"/>
       <limit effort="0.0" lower="-3.14159" upper="3.14159" velocity="0.0"/>
    </joint>
</robot>