<robot name = "robot">
    <link name="link0">
        <inertial>
            <origin xyz="-1.103910391925338 -1.3934077213191656 0.6210115933257018" rpy="0 0 0"/>
            <mass value="1" />
            <inertia ixx="100" ixy="0" ixz="0" iyy="100" iyz="0" izz="100" />
        </inertial>
        <visual>
            <origin xyz="-1.103910391925338 -1.3934077213191656 0.6210115933257018" rpy="0 0 0"/>
            <geometry>
                <box size="1.3941171454887158 1.3941171454887158 1.3941171454887158" />
            </geometry>
            <material name="Blue">
                <color rgba="0 0 1 1"/>
            </material>
        </visual>
        <collision>
            <origin xyz="-1.103910391925338 -1.3934077213191656 0.6210115933257018" rpy="0 0 0"/>
            <geometry>
                <box size="1.3941171454887158 1.3941171454887158 1.3941171454887158" />
            </geometry>
        </collision>
    </link>
    <joint name="link0_link1" type="revolute">
       <parent link="link0"/>
       <child  link="link1"/>
       <origin rpy="0 0 0" xyz="1.3359902587578123 0.8076597987913037 1.290835739921795" />
       <axis xyz="1 0 0"/>
       <limit effort="0.0" lower="-3.14159" upper="3.14159" velocity="0.0"/>
    </joint>
    <link name="link1">
        <inertial>
            <origin xyz="-0.7636244805657191 -0.8213133999069676 1.3694651317793713" rpy="0 0 0"/>
            <mass value="1" />
            <inertia ixx="100" ixy="0" ixz="0" iyy="100" iyz="0" izz="100" />
        </inertial>
        <visual>
            <origin xyz="-0.7636244805657191 -0.8213133999069676 1.3694651317793713" rpy="0 0 0"/>
            <geometry>
                <box size="0.8858908890997076 0.8858908890997076 0.8858908890997076" />
            </geometry>
            <material name="Green">
                <color rgba="0 1 0 1"/>
            </material>
        </visual>
        <collision>
            <origin xyz="-0.7636244805657191 -0.8213133999069676 1.3694651317793713" rpy="0 0 0"/>
            <geometry>
                <box size="0.8858908890997076 0.8858908890997076 0.8858908890997076" />
            </geometry>
        </collision>
    </link>
    <joint name="link1_link2" type="revolute">
       <parent link="link1"/>
       <child  link="link2"/>
       <origin rpy="0 0 0" xyz="1.280147525411262 0.6154359999497544 0.6579466700042922" />
       <axis xyz="1 0 0"/>
       <limit effort="0.0" lower="-3.14159" upper="3.14159" velocity="0.0"/>
    </joint>
    <link name="link2">
        <inertial>
            <origin xyz="-1.418921923414623 -0.5397687231759918 1.363087152522363" rpy="0 0 0"/>
            <mass value="1" />
            <inertia ixx="100" ixy="0" ixz="0" iyy="100" iyz="0" izz="100" />
        </inertial>
        <visual>
            <origin xyz="-1.418921923414623 -0.5397687231759918 1.363087152522363" rpy="0 0 0"/>
            <geometry>
                <box size="0.9863747260399148 0.9863747260399148 0.9863747260399148" />
            </geometry>
            <material name="Green">
                <color rgba="0 1 0 1"/>
            </material>
        </visual>
        <collision>
            <origin xyz="-1.418921923414623 -0.5397687231759918 1.363087152522363" rpy="0 0 0"/>
            <geometry>
                <box size="0.9863747260399148 0.9863747260399148 0.9863747260399148" />
            </geometry>
        </collision>
    </link>
</robot>