<robot name = "robot">
    <link name="link1">
        <inertial>
            <origin xyz="0.29434130066862196 0 1.6872394628824283" rpy="0 0 0"/>
            <mass value="2.177722086738973" />
            <inertia ixx="100" ixy="0" ixz="0" iyy="100" iyz="0" izz="100" />
        </inertial>
        <visual>
            <origin xyz="0.29434130066862196 0 1.6872394628824283" rpy="0 0 0"/>
            <geometry>
                <box size="0.5886826013372439 0.7137672993085826 1.6872394628824283" />
            </geometry>
            <material name="Blue">
                <color rgba="0 0 1 1"/>
            </material>
        </visual>
        <collision>
            <origin xyz="0.29434130066862196 0 1.6872394628824283" rpy="0 0 0"/>
            <geometry>
                <box size="0.5886826013372439 0.7137672993085826 1.6872394628824283" />
            </geometry>
        </collision>
    </link>
    <joint name="link1_link2" type="revolute">
       <parent link="link1"/>
       <child  link="link2"/>
       <origin rpy="0 0 0" xyz="0.5886826013372439 0 1.6872394628824283" />
       <axis xyz="0 1 0"/>
       <limit effort="0.0" lower="-3.14159" upper="3.14159" velocity="0.0"/>
    </joint>
    <link name="link2">
        <inertial>
            <origin xyz="0.26945454592143914 0 0" rpy="0 0 0"/>
            <mass value="1.8508972923901246" />
            <inertia ixx="100" ixy="0" ixz="0" iyy="100" iyz="0" izz="100" />
        </inertial>
        <visual>
            <origin xyz="0.26945454592143914 0 0" rpy="0 0 0"/>
            <geometry>
                <box size="0.5389090918428783 1.0501827919943099 1.7796709749368869" />
            </geometry>
            <material name="Blue">
                <color rgba="0 0 1 1"/>
            </material>
        </visual>
        <collision>
            <origin xyz="0.26945454592143914 0 0" rpy="0 0 0"/>
            <geometry>
                <box size="0.5389090918428783 1.0501827919943099 1.7796709749368869" />
            </geometry>
        </collision>
    </link>
    <joint name="link2_link3" type="revolute">
       <parent link="link2"/>
       <child  link="link3"/>
       <origin rpy="0 0 0" xyz="0.5389090918428783 0 0" />
       <axis xyz="0 1 0"/>
       <limit effort="0.0" lower="-3.14159" upper="3.14159" velocity="0.0"/>
    </joint>
    <link name="link3">
        <inertial>
            <origin xyz="0.36383450693368924 0 0" rpy="0 0 0"/>
            <mass value="1.276770374382461" />
            <inertia ixx="100" ixy="0" ixz="0" iyy="100" iyz="0" izz="100" />
        </inertial>
        <visual>
            <origin xyz="0.36383450693368924 0 0" rpy="0 0 0"/>
            <geometry>
                <box size="0.7276690138673785 2.167523832617442 2.1979198245575757" />
            </geometry>
            <material name="Blue">
                <color rgba="0 0 1 1"/>
            </material>
        </visual>
        <collision>
            <origin xyz="0.36383450693368924 0 0" rpy="0 0 0"/>
            <geometry>
                <box size="0.7276690138673785 2.167523832617442 2.1979198245575757" />
            </geometry>
        </collision>
    </link>
    <joint name="link3_link4" type="revolute">
       <parent link="link3"/>
       <child  link="link4"/>
       <origin rpy="0 0 0" xyz="0.7276690138673785 0 0" />
       <axis xyz="0 1 0"/>
       <limit effort="0.0" lower="-3.14159" upper="3.14159" velocity="0.0"/>
    </joint>
    <link name="link4">
        <inertial>
            <origin xyz="0.921342700652852 0 0" rpy="0 0 0"/>
            <mass value="2.8231485176342517" />
            <inertia ixx="100" ixy="0" ixz="0" iyy="100" iyz="0" izz="100" />
        </inertial>
        <visual>
            <origin xyz="0.921342700652852 0 0" rpy="0 0 0"/>
            <geometry>
                <box size="1.842685401305704 1.9845928237759765 0.7857461201516429" />
            </geometry>
            <material name="Green">
                <color rgba="0 1 0 1"/>
            </material>
        </visual>
        <collision>
            <origin xyz="0.921342700652852 0 0" rpy="0 0 0"/>
            <geometry>
                <box size="1.842685401305704 1.9845928237759765 0.7857461201516429" />
            </geometry>
        </collision>
    </link>
</robot>