<robot name = "robot">
    <link name="link1">
        <inertial>
            <origin xyz="1.0840655489922333 0 0" rpy="0 0 0"/>
            <mass value="3.798663505993619" />
            <inertia ixx="100" ixy="0" ixz="0" iyy="100" iyz="0" izz="100" />
        </inertial>
        <visual>
            <origin xyz="1.0840655489922333 0 0" rpy="0 0 0"/>
            <geometry>
                <box size="2.1681310979844666 1.9546504833205403 1.6532021905903542" />
            </geometry>
            <material name="Blue">
                <color rgba="0 0 1 1"/>
            </material>
        </visual>
        <collision>
            <origin xyz="1.0840655489922333 0 0" rpy="0 0 0"/>
            <geometry>
                <box size="2.1681310979844666 1.9546504833205403 1.6532021905903542" />
            </geometry>
        </collision>
    </link>
    <joint name="link1_link2" type="revolute">
       <parent link="link1"/>
       <child  link="link2"/>
       <origin rpy="0 0 0" xyz="2.1681310979844666 0 0" />
       <axis xyz="0 1 0"/>
       <limit effort="0.0" lower="-3.14159" upper="3.14159" velocity="0.0"/>
    </joint>
    <link name="link2">
        <inertial>
            <origin xyz="0.2792276779379089 0 0" rpy="0 0 0"/>
            <mass value="0.1042664700510676" />
            <inertia ixx="100" ixy="0" ixz="0" iyy="100" iyz="0" izz="100" />
        </inertial>
        <visual>
            <origin xyz="0.2792276779379089 0 0" rpy="0 0 0"/>
            <geometry>
                <box size="0.5584553558758178 0.809321799051185 1.4144910667436301" />
            </geometry>
            <material name="Green">
                <color rgba="0 1 0 1"/>
            </material>
        </visual>
        <collision>
            <origin xyz="0.2792276779379089 0 0" rpy="0 0 0"/>
            <geometry>
                <box size="0.5584553558758178 0.809321799051185 1.4144910667436301" />
            </geometry>
        </collision>
    </link>
    <joint name="link2_link3" type="revolute">
       <parent link="link2"/>
       <child  link="link3"/>
       <origin rpy="0 0 0" xyz="0.5584553558758178 0 0" />
       <axis xyz="0 1 0"/>
       <limit effort="0.0" lower="-3.14159" upper="3.14159" velocity="0.0"/>
    </joint>
    <link name="link3">
        <inertial>
            <origin xyz="1.0527727076585662 0 0" rpy="0 0 0"/>
            <mass value="0.9388419124094066" />
            <inertia ixx="100" ixy="0" ixz="0" iyy="100" iyz="0" izz="100" />
        </inertial>
        <visual>
            <origin xyz="1.0527727076585662 0 0" rpy="0 0 0"/>
            <geometry>
                <box size="2.1055454153171325 2.340374676602882 2.064797751797774" />
            </geometry>
            <material name="Green">
                <color rgba="0 1 0 1"/>
            </material>
        </visual>
        <collision>
            <origin xyz="1.0527727076585662 0 0" rpy="0 0 0"/>
            <geometry>
                <box size="2.1055454153171325 2.340374676602882 2.064797751797774" />
            </geometry>
        </collision>
    </link>
    <joint name="link3_link4" type="revolute">
       <parent link="link3"/>
       <child  link="link4"/>
       <origin rpy="0 0 0" xyz="2.1055454153171325 0 0" />
       <axis xyz="0 1 0"/>
       <limit effort="0.0" lower="-3.14159" upper="3.14159" velocity="0.0"/>
    </joint>
    <link name="link4">
        <inertial>
            <origin xyz="0.546848852580364 0 0" rpy="0 0 0"/>
            <mass value="0.2421340325638499" />
            <inertia ixx="100" ixy="0" ixz="0" iyy="100" iyz="0" izz="100" />
        </inertial>
        <visual>
            <origin xyz="0.546848852580364 0 0" rpy="0 0 0"/>
            <geometry>
                <box size="1.093697705160728 0.7902872201787827 0.8439647615053572" />
            </geometry>
            <material name="Blue">
                <color rgba="0 0 1 1"/>
            </material>
        </visual>
        <collision>
            <origin xyz="0.546848852580364 0 0" rpy="0 0 0"/>
            <geometry>
                <box size="1.093697705160728 0.7902872201787827 0.8439647615053572" />
            </geometry>
        </collision>
    </link>
    <joint name="link4_link5" type="revolute">
       <parent link="link4"/>
       <child  link="link5"/>
       <origin rpy="0 0 0" xyz="1.093697705160728 0 0" />
       <axis xyz="0 1 0"/>
       <limit effort="0.0" lower="-3.14159" upper="3.14159" velocity="0.0"/>
    </joint>
    <link name="link5">
        <inertial>
            <origin xyz="0.6859547499931699 0 0" rpy="0 0 0"/>
            <mass value="2.1958066847564286" />
            <inertia ixx="100" ixy="0" ixz="0" iyy="100" iyz="0" izz="100" />
        </inertial>
        <visual>
            <origin xyz="0.6859547499931699 0 0" rpy="0 0 0"/>
            <geometry>
                <box size="1.3719094999863397 2.2663414371984967 2.2124868282407038" />
            </geometry>
            <material name="Blue">
                <color rgba="0 0 1 1"/>
            </material>
        </visual>
        <collision>
            <origin xyz="0.6859547499931699 0 0" rpy="0 0 0"/>
            <geometry>
                <box size="1.3719094999863397 2.2663414371984967 2.2124868282407038" />
            </geometry>
        </collision>
    </link>
    <joint name="link5_link6" type="revolute">
       <parent link="link5"/>
       <child  link="link6"/>
       <origin rpy="0 0 0" xyz="1.3719094999863397 0 0" />
       <axis xyz="0 1 0"/>
       <limit effort="0.0" lower="-3.14159" upper="3.14159" velocity="0.0"/>
    </joint>
    <link name="link6">
        <inertial>
            <origin xyz="0.6021518239484631 0 0" rpy="0 0 0"/>
            <mass value="4.329982891495016" />
            <inertia ixx="100" ixy="0" ixz="0" iyy="100" iyz="0" izz="100" />
        </inertial>
        <visual>
            <origin xyz="0.6021518239484631 0 0" rpy="0 0 0"/>
            <geometry>
                <box size="1.2043036478969262 0.5738860312233407 2.3806809013379606" />
            </geometry>
            <material name="Green">
                <color rgba="0 1 0 1"/>
            </material>
        </visual>
        <collision>
            <origin xyz="0.6021518239484631 0 0" rpy="0 0 0"/>
            <geometry>
                <box size="1.2043036478969262 0.5738860312233407 2.3806809013379606" />
            </geometry>
        </collision>
    </link>
    <joint name="link6_link7" type="revolute">
       <parent link="link6"/>
       <child  link="link7"/>
       <origin rpy="0 0 0" xyz="1.2043036478969262 0 0" />
       <axis xyz="0 1 0"/>
       <limit effort="0.0" lower="-3.14159" upper="3.14159" velocity="0.0"/>
    </joint>
    <link name="link7">
        <inertial>
            <origin xyz="0.6021518239484631 0 0" rpy="0 0 0"/>
            <mass value="4.522658602844529" />
            <inertia ixx="100" ixy="0" ixz="0" iyy="100" iyz="0" izz="100" />
        </inertial>
        <visual>
            <origin xyz="0.6021518239484631 0 0" rpy="0 0 0"/>
            <geometry>
                <box size="1.2043036478969262 2.4357945867911006 2.1671053491001846" />
            </geometry>
            <material name="Blue">
                <color rgba="0 0 1 1"/>
            </material>
        </visual>
        <collision>
            <origin xyz="0.6021518239484631 0 0" rpy="0 0 0"/>
            <geometry>
                <box size="1.2043036478969262 2.4357945867911006 2.1671053491001846" />
            </geometry>
        </collision>
    </link>
</robot>