<robot name = "robot">
    <link name="link1">
        <inertial>
            <origin xyz="0.4587256660645953 0 1.5523960143713076" rpy="0 0 0"/>
            <mass value="3.6355908362784186" />
            <inertia ixx="100" ixy="0" ixz="0" iyy="100" iyz="0" izz="100" />
        </inertial>
        <visual>
            <origin xyz="0.4587256660645953 0 1.5523960143713076" rpy="0 0 0"/>
            <geometry>
                <box size="0.9174513321291906 1.6599805481907115 1.5523960143713076" />
            </geometry>
            <material name="Blue">
                <color rgba="0 0 1 1"/>
            </material>
        </visual>
        <collision>
            <origin xyz="0.4587256660645953 0 1.5523960143713076" rpy="0 0 0"/>
            <geometry>
                <box size="0.9174513321291906 1.6599805481907115 1.5523960143713076" />
            </geometry>
        </collision>
    </link>
    <joint name="link1_link2" type="revolute">
       <parent link="link1"/>
       <child  link="link2"/>
       <origin rpy="0 0 0" xyz="0.9174513321291906 0 1.5523960143713076" />
       <axis xyz="0 0 1"/>
       <limit effort="0.0" lower="-3.14159" upper="3.14159" velocity="0.0"/>
    </joint>
    <link name="link2">
        <inertial>
            <origin xyz="0.5507311674326307 0 0" rpy="0 0 0"/>
            <mass value="2.9217673868040936" />
            <inertia ixx="100" ixy="0" ixz="0" iyy="100" iyz="0" izz="100" />
        </inertial>
        <visual>
            <origin xyz="0.5507311674326307 0 0" rpy="0 0 0"/>
            <geometry>
                <box size="1.1014623348652615 1.8556890065829899 1.9162702702713679" />
            </geometry>
            <material name="Green">
                <color rgba="0 1 0 1"/>
            </material>
        </visual>
        <collision>
            <origin xyz="0.5507311674326307 0 0" rpy="0 0 0"/>
            <geometry>
                <box size="1.1014623348652615 1.8556890065829899 1.9162702702713679" />
            </geometry>
        </collision>
    </link>
    <joint name="link2_link3" type="revolute">
       <parent link="link2"/>
       <child  link="link3"/>
       <origin rpy="0 0 0" xyz="1.1014623348652615 0 0" />
       <axis xyz="0 0 1"/>
       <limit effort="0.0" lower="-3.14159" upper="3.14159" velocity="0.0"/>
    </joint>
    <link name="link3">
        <inertial>
            <origin xyz="1.1582821312942673 0 0" rpy="0 0 0"/>
            <mass value="3.159860612965357" />
            <inertia ixx="100" ixy="0" ixz="0" iyy="100" iyz="0" izz="100" />
        </inertial>
        <visual>
            <origin xyz="1.1582821312942673 0 0" rpy="0 0 0"/>
            <geometry>
                <box size="2.3165642625885345 0.9629919024797893 2.0512985399203076" />
            </geometry>
            <material name="Green">
                <color rgba="0 1 0 1"/>
            </material>
        </visual>
        <collision>
            <origin xyz="1.1582821312942673 0 0" rpy="0 0 0"/>
            <geometry>
                <box size="2.3165642625885345 0.9629919024797893 2.0512985399203076" />
            </geometry>
        </collision>
    </link>
    <joint name="link3_link4" type="revolute">
       <parent link="link3"/>
       <child  link="link4"/>
       <origin rpy="0 0 0" xyz="2.3165642625885345 0 0" />
       <axis xyz="0 0 1"/>
       <limit effort="0.0" lower="-3.14159" upper="3.14159" velocity="0.0"/>
    </joint>
    <link name="link4">
        <inertial>
            <origin xyz="1.0813939625013393 0 0" rpy="0 0 0"/>
            <mass value="0.06407120806805056" />
            <inertia ixx="100" ixy="0" ixz="0" iyy="100" iyz="0" izz="100" />
        </inertial>
        <visual>
            <origin xyz="1.0813939625013393 0 0" rpy="0 0 0"/>
            <geometry>
                <box size="2.1627879250026787 2.4114437842699576 2.02796818918205" />
            </geometry>
            <material name="Blue">
                <color rgba="0 0 1 1"/>
            </material>
        </visual>
        <collision>
            <origin xyz="1.0813939625013393 0 0" rpy="0 0 0"/>
            <geometry>
                <box size="2.1627879250026787 2.4114437842699576 2.02796818918205" />
            </geometry>
        </collision>
    </link>
    <joint name="link4_link5" type="revolute">
       <parent link="link4"/>
       <child  link="link5"/>
       <origin rpy="0 0 0" xyz="2.1627879250026787 0 0" />
       <axis xyz="0 0 1"/>
       <limit effort="0.0" lower="-3.14159" upper="3.14159" velocity="0.0"/>
    </joint>
    <link name="link5">
        <inertial>
            <origin xyz="1.0822739665933536 0 0" rpy="0 0 0"/>
            <mass value="1.1245890930196856" />
            <inertia ixx="100" ixy="0" ixz="0" iyy="100" iyz="0" izz="100" />
        </inertial>
        <visual>
            <origin xyz="1.0822739665933536 0 0" rpy="0 0 0"/>
            <geometry>
                <box size="2.1645479331867072 2.1620304648555777 1.7080884388884165" />
            </geometry>
            <material name="Green">
                <color rgba="0 1 0 1"/>
            </material>
        </visual>
        <collision>
            <origin xyz="1.0822739665933536 0 0" rpy="0 0 0"/>
            <geometry>
                <box size="2.1645479331867072 2.1620304648555777 1.7080884388884165" />
            </geometry>
        </collision>
    </link>
</robot>