<robot name = "robot">
    <link name="link0">
        <inertial>
            <origin xyz="0 0 0.59586076401173" rpy="0 0 0"/>
            <mass value="1" />
            <inertia ixx="100" ixy="0" ixz="0" iyy="100" iyz="0" izz="100" />
        </inertial>
        <visual>
            <origin xyz="0 0 0.59586076401173" rpy="0 0 0"/>
            <geometry>
                <box size="0.31902781811705366 0.23817637164991387 0.59586076401173" />
            </geometry>
            <material name="Green">
                <color rgba="0 1 0 1"/>
            </material>
        </visual>
        <collision>
            <origin xyz="0 0 0.59586076401173" rpy="0 0 0"/>
            <geometry>
                <box size="0.31902781811705366 0.23817637164991387 0.59586076401173" />
            </geometry>
        </collision>
    </link>
    <link name="link1">
        <inertial>
            <origin xyz="0 0 0.59586076401173" rpy="0 0 0"/>
            <mass value="1" />
            <inertia ixx="100" ixy="0" ixz="0" iyy="100" iyz="0" izz="100" />
        </inertial>
        <visual>
            <origin xyz="0 0 0.59586076401173" rpy="0 0 0"/>
            <geometry>
                <box size="0.31902781811705366 0.23817637164991387 0.59586076401173" />
            </geometry>
            <material name="Blue">
                <color rgba="0 0 1 1"/>
            </material>
        </visual>
        <collision>
            <origin xyz="0 0 0.59586076401173" rpy="0 0 0"/>
            <geometry>
                <box size="0.31902781811705366 0.23817637164991387 0.59586076401173" />
            </geometry>
        </collision>
    </link>
    <link name="link2">
        <inertial>
            <origin xyz="0 0.3386254948877946 0" rpy="0 0 0"/>
            <mass value="1" />
            <inertia ixx="100" ixy="0" ixz="0" iyy="100" iyz="0" izz="100" />
        </inertial>
        <visual>
            <origin xyz="0 0.3386254948877946 0" rpy="0 0 0"/>
            <geometry>
                <box size="0.9848244416424998 0.6772509897755892 0.3267883794753389" />
            </geometry>
            <material name="Green">
                <color rgba="0 1 0 1"/>
            </material>
        </visual>
        <collision>
            <origin xyz="0 0.3386254948877946 0" rpy="0 0 0"/>
            <geometry>
                <box size="0.9848244416424998 0.6772509897755892 0.3267883794753389" />
            </geometry>
        </collision>
    </link>
    <link name="link3">
        <inertial>
            <origin xyz="0.3253070175083542 0 0" rpy="0 0 0"/>
            <mass value="1" />
            <inertia ixx="100" ixy="0" ixz="0" iyy="100" iyz="0" izz="100" />
        </inertial>
        <visual>
            <origin xyz="0.3253070175083542 0 0" rpy="0 0 0"/>
            <geometry>
                <box size="0.6506140350167084 0.5638194275469663 0.9514693436715211" />
            </geometry>
            <material name="Green">
                <color rgba="0 1 0 1"/>
            </material>
        </visual>
        <collision>
            <origin xyz="0.3253070175083542 0 0" rpy="0 0 0"/>
            <geometry>
                <box size="0.6506140350167084 0.5638194275469663 0.9514693436715211" />
            </geometry>
        </collision>
    </link>
    <link name="link4">
        <inertial>
            <origin xyz="0 0 0.45477958086634673" rpy="0 0 0"/>
            <mass value="1" />
            <inertia ixx="100" ixy="0" ixz="0" iyy="100" iyz="0" izz="100" />
        </inertial>
        <visual>
            <origin xyz="0 0 0.45477958086634673" rpy="0 0 0"/>
            <geometry>
                <box size="0.7102208819219964 0.7020414126144296 0.9095591617326935" />
            </geometry>
            <material name="Green">
                <color rgba="0 1 0 1"/>
            </material>
        </visual>
        <collision>
            <origin xyz="0 0 0.45477958086634673" rpy="0 0 0"/>
            <geometry>
                <box size="0.7102208819219964 0.7020414126144296 0.9095591617326935" />
            </geometry>
        </collision>
    </link>
    <link name="link5">
        <inertial>
            <origin xyz="0 0.4968252312305842 0" rpy="0 0 0"/>
            <mass value="1" />
            <inertia ixx="100" ixy="0" ixz="0" iyy="100" iyz="0" izz="100" />
        </inertial>
        <visual>
            <origin xyz="0 0.4968252312305842 0" rpy="0 0 0"/>
            <geometry>
                <box size="0.5720359850583352 0.9936504624611684 0.3902019549213683" />
            </geometry>
            <material name="Blue">
                <color rgba="0 0 1 1"/>
            </material>
        </visual>
        <collision>
            <origin xyz="0 0.4968252312305842 0" rpy="0 0 0"/>
            <geometry>
                <box size="0.5720359850583352 0.9936504624611684 0.3902019549213683" />
            </geometry>
        </collision>
    </link>
    <joint name="link0_link1" type="revolute">
       <parent link="link0"/>
       <child  link="link1"/>
       <origin rpy="0 0 0" xyz="0 0 0.59586076401173" />
       <axis xyz="0 1 0"/>
       <limit effort="0.0" lower="-3.14159" upper="3.14159" velocity="0.0"/>
    </joint>
    <joint name="link1_link2" type="revolute">
       <parent link="link1"/>
       <child  link="link2"/>
       <origin rpy="0 0 0" xyz="0 0.11908818582495694 0.297930382005865" />
       <axis xyz="0 0 1"/>
       <limit effort="0.0" lower="-3.14159" upper="3.14159" velocity="0.0"/>
    </joint>
    <joint name="link2_link3" type="revolute">
       <parent link="link2"/>
       <child  link="link3"/>
       <origin rpy="0 0 0" xyz="0.4924122208212499 0.3386254948877946 0" />
       <axis xyz="0 0 1"/>
       <limit effort="0.0" lower="-3.14159" upper="3.14159" velocity="0.0"/>
    </joint>
    <joint name="link3_link4" type="revolute">
       <parent link="link3"/>
       <child  link="link4"/>
       <origin rpy="0 0 0" xyz="0.3253070175083542 0 0.47573467183576057" />
       <axis xyz="0 0 1"/>
       <limit effort="0.0" lower="-3.14159" upper="3.14159" velocity="0.0"/>
    </joint>
    <joint name="link4_link5" type="revolute">
       <parent link="link4"/>
       <child  link="link5"/>
       <origin rpy="0 0 0" xyz="0 0.3510207063072148 0.45477958086634673" />
       <axis xyz="1 0 0"/>
       <limit effort="0.0" lower="-3.14159" upper="3.14159" velocity="0.0"/>
    </joint>
</robot>