<robot name = "robot">
    <link name="link1">
        <inertial>
            <origin xyz="0.5685042224966104 0 0" rpy="0 0 0"/>
            <mass value="4.106872566472319" />
            <inertia ixx="100" ixy="0" ixz="0" iyy="100" iyz="0" izz="100" />
        </inertial>
        <visual>
            <origin xyz="0.5685042224966104 0 0" rpy="0 0 0"/>
            <geometry>
                <box size="1.1370084449932207 1.776977119422215 1.8979868436234915" />
            </geometry>
            <material name="Green">
                <color rgba="0 1 0 1"/>
            </material>
        </visual>
        <collision>
            <origin xyz="0.5685042224966104 0 0" rpy="0 0 0"/>
            <geometry>
                <box size="1.1370084449932207 1.776977119422215 1.8979868436234915" />
            </geometry>
        </collision>
    </link>
    <joint name="link1_link2" type="revolute">
       <parent link="link1"/>
       <child  link="link2"/>
       <origin rpy="0 0 0" xyz="1.1370084449932207 0 0" />
       <axis xyz="0 1 0"/>
       <limit effort="0.0" lower="-3.14159" upper="3.14159" velocity="0.0"/>
    </joint>
    <link name="link2">
        <inertial>
            <origin xyz="0.7059069182311053 0 0" rpy="0 0 0"/>
            <mass value="2.775071715653663" />
            <inertia ixx="100" ixy="0" ixz="0" iyy="100" iyz="0" izz="100" />
        </inertial>
        <visual>
            <origin xyz="0.7059069182311053 0 0" rpy="0 0 0"/>
            <geometry>
                <box size="1.4118138364622106 2.010955793127295 1.2262156645504265" />
            </geometry>
            <material name="Blue">
                <color rgba="0 0 1 1"/>
            </material>
        </visual>
        <collision>
            <origin xyz="0.7059069182311053 0 0" rpy="0 0 0"/>
            <geometry>
                <box size="1.4118138364622106 2.010955793127295 1.2262156645504265" />
            </geometry>
        </collision>
    </link>
    <joint name="link2_link3" type="revolute">
       <parent link="link2"/>
       <child  link="link3"/>
       <origin rpy="0 0 0" xyz="1.4118138364622106 0 0" />
       <axis xyz="0 1 0"/>
       <limit effort="0.0" lower="-3.14159" upper="3.14159" velocity="0.0"/>
    </joint>
    <link name="link3">
        <inertial>
            <origin xyz="0.6212471625418078 0 0" rpy="0 0 0"/>
            <mass value="4.604978418214236" />
            <inertia ixx="100" ixy="0" ixz="0" iyy="100" iyz="0" izz="100" />
        </inertial>
        <visual>
            <origin xyz="0.6212471625418078 0 0" rpy="0 0 0"/>
            <geometry>
                <box size="1.2424943250836156 1.6521199979142847 2.4274015788791434" />
            </geometry>
            <material name="Green">
                <color rgba="0 1 0 1"/>
            </material>
        </visual>
        <collision>
            <origin xyz="0.6212471625418078 0 0" rpy="0 0 0"/>
            <geometry>
                <box size="1.2424943250836156 1.6521199979142847 2.4274015788791434" />
            </geometry>
        </collision>
    </link>
    <joint name="link3_link4" type="revolute">
       <parent link="link3"/>
       <child  link="link4"/>
       <origin rpy="0 0 0" xyz="1.2424943250836156 0 0" />
       <axis xyz="0 1 0"/>
       <limit effort="0.0" lower="-3.14159" upper="3.14159" velocity="0.0"/>
    </joint>
    <link name="link4">
        <inertial>
            <origin xyz="0.5898882384537942 0 0" rpy="0 0 0"/>
            <mass value="0.6079835259703259" />
            <inertia ixx="100" ixy="0" ixz="0" iyy="100" iyz="0" izz="100" />
        </inertial>
        <visual>
            <origin xyz="0.5898882384537942 0 0" rpy="0 0 0"/>
            <geometry>
                <box size="1.1797764769075885 1.4658315314210388 0.885417911056902" />
            </geometry>
            <material name="Blue">
                <color rgba="0 0 1 1"/>
            </material>
        </visual>
        <collision>
            <origin xyz="0.5898882384537942 0 0" rpy="0 0 0"/>
            <geometry>
                <box size="1.1797764769075885 1.4658315314210388 0.885417911056902" />
            </geometry>
        </collision>
    </link>
    <joint name="link4_link5" type="revolute">
       <parent link="link4"/>
       <child  link="link5"/>
       <origin rpy="0 0 0" xyz="1.1797764769075885 0 0" />
       <axis xyz="0 1 0"/>
       <limit effort="0.0" lower="-3.14159" upper="3.14159" velocity="0.0"/>
    </joint>
    <link name="link5">
        <inertial>
            <origin xyz="0.6885987093486726 0 0" rpy="0 0 0"/>
            <mass value="4.350830326676799" />
            <inertia ixx="100" ixy="0" ixz="0" iyy="100" iyz="0" izz="100" />
        </inertial>
        <visual>
            <origin xyz="0.6885987093486726 0 0" rpy="0 0 0"/>
            <geometry>
                <box size="1.3771974186973452 2.154697631654708 2.359107590602034" />
            </geometry>
            <material name="Green">
                <color rgba="0 1 0 1"/>
            </material>
        </visual>
        <collision>
            <origin xyz="0.6885987093486726 0 0" rpy="0 0 0"/>
            <geometry>
                <box size="1.3771974186973452 2.154697631654708 2.359107590602034" />
            </geometry>
        </collision>
    </link>
    <joint name="link5_link6" type="revolute">
       <parent link="link5"/>
       <child  link="link6"/>
       <origin rpy="0 0 0" xyz="1.3771974186973452 0 0" />
       <axis xyz="0 1 0"/>
       <limit effort="0.0" lower="-3.14159" upper="3.14159" velocity="0.0"/>
    </joint>
    <link name="link6">
        <inertial>
            <origin xyz="1.2490549601737877 0 0" rpy="0 0 0"/>
            <mass value="2.059684380574808" />
            <inertia ixx="100" ixy="0" ixz="0" iyy="100" iyz="0" izz="100" />
        </inertial>
        <visual>
            <origin xyz="1.2490549601737877 0 0" rpy="0 0 0"/>
            <geometry>
                <box size="2.4981099203475754 1.9735797470690954 0.8962240134615234" />
            </geometry>
            <material name="Green">
                <color rgba="0 1 0 1"/>
            </material>
        </visual>
        <collision>
            <origin xyz="1.2490549601737877 0 0" rpy="0 0 0"/>
            <geometry>
                <box size="2.4981099203475754 1.9735797470690954 0.8962240134615234" />
            </geometry>
        </collision>
    </link>
    <joint name="link6_link7" type="revolute">
       <parent link="link6"/>
       <child  link="link7"/>
       <origin rpy="0 0 0" xyz="2.4981099203475754 0 0" />
       <axis xyz="0 1 0"/>
       <limit effort="0.0" lower="-3.14159" upper="3.14159" velocity="0.0"/>
    </joint>
    <link name="link7">
        <inertial>
            <origin xyz="0.7038365683222754 0 0" rpy="0 0 0"/>
            <mass value="4.853524763573348" />
            <inertia ixx="100" ixy="0" ixz="0" iyy="100" iyz="0" izz="100" />
        </inertial>
        <visual>
            <origin xyz="0.7038365683222754 0 0" rpy="0 0 0"/>
            <geometry>
                <box size="1.4076731366445507 1.463111999008486 1.60364304770967" />
            </geometry>
            <material name="Blue">
                <color rgba="0 0 1 1"/>
            </material>
        </visual>
        <collision>
            <origin xyz="0.7038365683222754 0 0" rpy="0 0 0"/>
            <geometry>
                <box size="1.4076731366445507 1.463111999008486 1.60364304770967" />
            </geometry>
        </collision>
    </link>
    <joint name="link7_link8" type="revolute">
       <parent link="link7"/>
       <child  link="link8"/>
       <origin rpy="0 0 0" xyz="1.4076731366445507 0 0" />
       <axis xyz="0 1 0"/>
       <limit effort="0.0" lower="-3.14159" upper="3.14159" velocity="0.0"/>
    </joint>
    <link name="link8">
        <inertial>
            <origin xyz="0.5238320729244528 0 0" rpy="0 0 0"/>
            <mass value="0.8896547422538897" />
            <inertia ixx="100" ixy="0" ixz="0" iyy="100" iyz="0" izz="100" />
        </inertial>
        <visual>
            <origin xyz="0.5238320729244528 0 0" rpy="0 0 0"/>
            <geometry>
                <box size="1.0476641458489055 1.4555388516660257 2.175649103398759" />
            </geometry>
            <material name="Green">
                <color rgba="0 1 0 1"/>
            </material>
        </visual>
        <collision>
            <origin xyz="0.5238320729244528 0 0" rpy="0 0 0"/>
            <geometry>
                <box size="1.0476641458489055 1.4555388516660257 2.175649103398759" />
            </geometry>
        </collision>
    </link>
    <joint name="link8_link9" type="revolute">
       <parent link="link8"/>
       <child  link="link9"/>
       <origin rpy="0 0 0" xyz="1.0476641458489055 0 0" />
       <axis xyz="0 1 0"/>
       <limit effort="0.0" lower="-3.14159" upper="3.14159" velocity="0.0"/>
    </joint>
    <link name="link9">
        <inertial>
            <origin xyz="0.7879954284068749 0 0" rpy="0 0 0"/>
            <mass value="3.0213214817489584" />
            <inertia ixx="100" ixy="0" ixz="0" iyy="100" iyz="0" izz="100" />
        </inertial>
        <visual>
            <origin xyz="0.7879954284068749 0 0" rpy="0 0 0"/>
            <geometry>
                <box size="1.5759908568137497 1.9757121823453956 1.3984644717941375" />
            </geometry>
            <material name="Blue">
                <color rgba="0 0 1 1"/>
            </material>
        </visual>
        <collision>
            <origin xyz="0.7879954284068749 0 0" rpy="0 0 0"/>
            <geometry>
                <box size="1.5759908568137497 1.9757121823453956 1.3984644717941375" />
            </geometry>
        </collision>
    </link>
    <joint name="link9_link10" type="revolute">
       <parent link="link9"/>
       <child  link="link10"/>
       <origin rpy="0 0 0" xyz="1.5759908568137497 0 0" />
       <axis xyz="0 1 0"/>
       <limit effort="0.0" lower="-3.14159" upper="3.14159" velocity="0.0"/>
    </joint>
    <link name="link10">
        <inertial>
            <origin xyz="0.7879954284068749 0 0" rpy="0 0 0"/>
            <mass value="2.744179784938587" />
            <inertia ixx="100" ixy="0" ixz="0" iyy="100" iyz="0" izz="100" />
        </inertial>
        <visual>
            <origin xyz="0.7879954284068749 0 0" rpy="0 0 0"/>
            <geometry>
                <box size="1.5759908568137497 0.5463651380497547 2.424454794319167" />
            </geometry>
            <material name="Blue">
                <color rgba="0 0 1 1"/>
            </material>
        </visual>
        <collision>
            <origin xyz="0.7879954284068749 0 0" rpy="0 0 0"/>
            <geometry>
                <box size="1.5759908568137497 0.5463651380497547 2.424454794319167" />
            </geometry>
        </collision>
    </link>
</robot>