<robot name = "robot">
    <link name="rootLink">
        <inertial>
            <origin xyz="0 0 1" rpy="0 0 0"/>
            <mass value="10" />
            <inertia ixx="100" ixy="0" ixz="0" iyy="100" iyz="0" izz="100" />
        </inertial>
        <visual>
            <origin xyz="0 0 1" rpy="0 0 0"/>
            <geometry>
                <box size="1 1 1" />
            </geometry>
            <material name="Green">
                <color rgba="0 1 0 1"/>
            </material>
        </visual>
        <collision>
            <origin xyz="0 0 1" rpy="0 0 0"/>
            <geometry>
                <box size="1 1 1" />
            </geometry>
        </collision>
    </link>
    <joint name="rootLink_link1NPP" type="revolute">
       <parent link="rootLink"/>
       <child  link="link1NPP"/>
       <origin rpy="0 0 0" xyz="0 0.5 0.5" />
       <axis xyz="0 1 0"/>
       <limit effort="0.0" lower="-3.14159" upper="3.14159" velocity="0.0"/>
    </joint>
    <joint name="rootLink_link1NNP" type="revolute">
       <parent link="rootLink"/>
       <child  link="link1NNP"/>
       <origin rpy="0 0 0" xyz="0 -0.5 0.5" />
       <axis xyz="0 1 0"/>
       <limit effort="0.0" lower="-3.14159" upper="3.14159" velocity="0.0"/>
    </joint>
    <link name="link1NPP">
        <inertial>
            <origin xyz="0 1 1" rpy="0 0 0"/>
            <mass value="1" />
            <inertia ixx="100" ixy="0" ixz="0" iyy="100" iyz="0" izz="100" />
        </inertial>
        <visual>
            <origin xyz="0 1 1" rpy="0 0 0"/>
            <geometry>
                <box size="0 0 1" />
            </geometry>
            <material name="Green">
                <color rgba="0 1 0 1"/>
            </material>
        </visual>
        <collision>
            <origin xyz="0 1 1" rpy="0 0 0"/>
            <geometry>
                <box size="0 0 1" />
            </geometry>
        </collision>
    </link>
    <link name="link2NPP">
        <inertial>
            <origin xyz="0 0.25729393851084215 0" rpy="0 0 0"/>
            <mass value="1" />
            <inertia ixx="100" ixy="0" ixz="0" iyy="100" iyz="0" izz="100" />
        </inertial>
        <visual>
            <origin xyz="0 0.25729393851084215 0" rpy="0 0 0"/>
            <geometry>
                <box size="0.4137602869524837 0.5145878770216843 0.35419800131036494" />
            </geometry>
            <material name="Green">
                <color rgba="0 1 0 1"/>
            </material>
        </visual>
        <collision>
            <origin xyz="0 0.25729393851084215 0" rpy="0 0 0"/>
            <geometry>
                <box size="0.4137602869524837 0.5145878770216843 0.35419800131036494" />
            </geometry>
        </collision>
    </link>
    <link name="link3NPP">
        <inertial>
            <origin xyz="0 0 0.23912862336301505" rpy="0 0 0"/>
            <mass value="1" />
            <inertia ixx="100" ixy="0" ixz="0" iyy="100" iyz="0" izz="100" />
        </inertial>
        <visual>
            <origin xyz="0 0 0.23912862336301505" rpy="0 0 0"/>
            <geometry>
                <box size="0.40013776814082347 0.323043346156267 0.4782572467260301" />
            </geometry>
            <material name="Green">
                <color rgba="0 1 0 1"/>
            </material>
        </visual>
        <collision>
            <origin xyz="0 0 0.23912862336301505" rpy="0 0 0"/>
            <geometry>
                <box size="0.40013776814082347 0.323043346156267 0.4782572467260301" />
            </geometry>
        </collision>
    </link>
    <link name="link4NPP">
        <inertial>
            <origin xyz="-0.2328292760077517 0 0" rpy="0 0 0"/>
            <mass value="1" />
            <inertia ixx="100" ixy="0" ixz="0" iyy="100" iyz="0" izz="100" />
        </inertial>
        <visual>
            <origin xyz="-0.2328292760077517 0 0" rpy="0 0 0"/>
            <geometry>
                <box size="0.4656585520155034 0.5636163043228186 0.6626761542701807" />
            </geometry>
            <material name="Green">
                <color rgba="0 1 0 1"/>
            </material>
        </visual>
        <collision>
            <origin xyz="-0.2328292760077517 0 0" rpy="0 0 0"/>
            <geometry>
                <box size="0.4656585520155034 0.5636163043228186 0.6626761542701807" />
            </geometry>
        </collision>
    </link>
    <link name="link1NNP">
        <inertial>
            <origin xyz="0 1 1" rpy="0 0 0"/>
            <mass value="1" />
            <inertia ixx="100" ixy="0" ixz="0" iyy="100" iyz="0" izz="100" />
        </inertial>
        <visual>
            <origin xyz="0 1 1" rpy="0 0 0"/>
            <geometry>
                <box size="0 0 1" />
            </geometry>
            <material name="Green">
                <color rgba="0 1 0 1"/>
            </material>
        </visual>
        <collision>
            <origin xyz="0 1 1" rpy="0 0 0"/>
            <geometry>
                <box size="0 0 1" />
            </geometry>
        </collision>
    </link>
    <link name="link2NNP">
        <inertial>
            <origin xyz="0 -0.25729393851084215 0" rpy="0 0 0"/>
            <mass value="1" />
            <inertia ixx="100" ixy="0" ixz="0" iyy="100" iyz="0" izz="100" />
        </inertial>
        <visual>
            <origin xyz="0 -0.25729393851084215 0" rpy="0 0 0"/>
            <geometry>
                <box size="0.4137602869524837 0.5145878770216843 0.35419800131036494" />
            </geometry>
            <material name="Green">
                <color rgba="0 1 0 1"/>
            </material>
        </visual>
        <collision>
            <origin xyz="0 -0.25729393851084215 0" rpy="0 0 0"/>
            <geometry>
                <box size="0.4137602869524837 0.5145878770216843 0.35419800131036494" />
            </geometry>
        </collision>
    </link>
    <link name="link3NNP">
        <inertial>
            <origin xyz="0 0 0.23912862336301505" rpy="0 0 0"/>
            <mass value="1" />
            <inertia ixx="100" ixy="0" ixz="0" iyy="100" iyz="0" izz="100" />
        </inertial>
        <visual>
            <origin xyz="0 0 0.23912862336301505" rpy="0 0 0"/>
            <geometry>
                <box size="0.40013776814082347 0.323043346156267 0.4782572467260301" />
            </geometry>
            <material name="Green">
                <color rgba="0 1 0 1"/>
            </material>
        </visual>
        <collision>
            <origin xyz="0 0 0.23912862336301505" rpy="0 0 0"/>
            <geometry>
                <box size="0.40013776814082347 0.323043346156267 0.4782572467260301" />
            </geometry>
        </collision>
    </link>
    <link name="link4NNP">
        <inertial>
            <origin xyz="-0.2328292760077517 0 0" rpy="0 0 0"/>
            <mass value="1" />
            <inertia ixx="100" ixy="0" ixz="0" iyy="100" iyz="0" izz="100" />
        </inertial>
        <visual>
            <origin xyz="-0.2328292760077517 0 0" rpy="0 0 0"/>
            <geometry>
                <box size="0.4656585520155034 0.5636163043228186 0.6626761542701807" />
            </geometry>
            <material name="Green">
                <color rgba="0 1 0 1"/>
            </material>
        </visual>
        <collision>
            <origin xyz="-0.2328292760077517 0 0" rpy="0 0 0"/>
            <geometry>
                <box size="0.4656585520155034 0.5636163043228186 0.6626761542701807" />
            </geometry>
        </collision>
    </link>
    <joint name="link1NPP_link2NPP" type="revolute">
       <parent link="link1NPP"/>
       <child  link="link2NPP"/>
       <origin rpy="0 0 0" xyz="0 0.0 0.5" />
       <axis xyz="0 1 0"/>
       <limit effort="0.0" lower="-3.14159" upper="3.14159" velocity="0.0"/>
    </joint>
    <joint name="link2NPP_link3NPP" type="revolute">
       <parent link="link2NPP"/>
       <child  link="link3NPP"/>
       <origin rpy="0 0 0" xyz="0 0.25729393851084215 0.17709900065518247" />
       <axis xyz="0 1 0"/>
       <limit effort="0.0" lower="-3.14159" upper="3.14159" velocity="0.0"/>
    </joint>
    <joint name="link3NPP_link4NPP" type="revolute">
       <parent link="link3NPP"/>
       <child  link="link4NPP"/>
       <origin rpy="0 0 0" xyz="-0.20006888407041173 0 0.23912862336301505" />
       <axis xyz="0 0 1"/>
       <limit effort="0.0" lower="-3.14159" upper="3.14159" velocity="0.0"/>
    </joint>
    <joint name="link1NNP_link2NNP" type="revolute">
       <parent link="link1NNP"/>
       <child  link="link2NNP"/>
       <origin rpy="0 0 0" xyz="0 0.0 0.5" />
       <axis xyz="0 1 0"/>
       <limit effort="0.0" lower="-3.14159" upper="3.14159" velocity="0.0"/>
    </joint>
    <joint name="link2NNP_link3NNP" type="revolute">
       <parent link="link2NNP"/>
       <child  link="link3NNP"/>
       <origin rpy="0 0 0" xyz="0 -0.25729393851084215 0.17709900065518247" />
       <axis xyz="0 1 0"/>
       <limit effort="0.0" lower="-3.14159" upper="3.14159" velocity="0.0"/>
    </joint>
    <joint name="link3NNP_link4NNP" type="revolute">
       <parent link="link3NNP"/>
       <child  link="link4NNP"/>
       <origin rpy="0 0 0" xyz="-0.20006888407041173 0 0.23912862336301505" />
       <axis xyz="0 0 1"/>
       <limit effort="0.0" lower="-3.14159" upper="3.14159" velocity="0.0"/>
    </joint>
</robot>