<robot name = "robot">
    <link name="rootLink">
        <inertial>
            <origin xyz="0 0 1" rpy="0 0 0"/>
            <mass value="10" />
            <inertia ixx="100" ixy="0" ixz="0" iyy="100" iyz="0" izz="100" />
        </inertial>
        <visual>
            <origin xyz="0 0 1" rpy="0 0 0"/>
            <geometry>
                <box size="1 1 1" />
            </geometry>
            <material name="Green">
                <color rgba="0 1 0 1"/>
            </material>
        </visual>
        <collision>
            <origin xyz="0 0 1" rpy="0 0 0"/>
            <geometry>
                <box size="1 1 1" />
            </geometry>
        </collision>
    </link>
    <joint name="rootLink_link1NPP" type="revolute">
       <parent link="rootLink"/>
       <child  link="link1NPP"/>
       <origin rpy="0 0 0" xyz="0 0.5 0.5" />
       <axis xyz="0 1 0"/>
       <limit effort="0.0" lower="-3.14159" upper="3.14159" velocity="0.0"/>
    </joint>
    <joint name="rootLink_link1NNP" type="revolute">
       <parent link="rootLink"/>
       <child  link="link1NNP"/>
       <origin rpy="0 0 0" xyz="0 -0.5 0.5" />
       <axis xyz="0 1 0"/>
       <limit effort="0.0" lower="-3.14159" upper="3.14159" velocity="0.0"/>
    </joint>
    <link name="link1NPP">
        <inertial>
            <origin xyz="0 1 1" rpy="0 0 0"/>
            <mass value="1" />
            <inertia ixx="100" ixy="0" ixz="0" iyy="100" iyz="0" izz="100" />
        </inertial>
        <visual>
            <origin xyz="0 1 1" rpy="0 0 0"/>
            <geometry>
                <box size="0 0 1" />
            </geometry>
            <material name="Blue">
                <color rgba="0 0 1 1"/>
            </material>
        </visual>
        <collision>
            <origin xyz="0 1 1" rpy="0 0 0"/>
            <geometry>
                <box size="0 0 1" />
            </geometry>
        </collision>
    </link>
    <link name="link2NPP">
        <inertial>
            <origin xyz="-0.38145701846620805 0 0" rpy="0 0 0"/>
            <mass value="1" />
            <inertia ixx="100" ixy="0" ixz="0" iyy="100" iyz="0" izz="100" />
        </inertial>
        <visual>
            <origin xyz="-0.38145701846620805 0 0" rpy="0 0 0"/>
            <geometry>
                <box size="0.7629140369324161 0.22519370970447983 0.9336151752919599" />
            </geometry>
            <material name="Green">
                <color rgba="0 1 0 1"/>
            </material>
        </visual>
        <collision>
            <origin xyz="-0.38145701846620805 0 0" rpy="0 0 0"/>
            <geometry>
                <box size="0.7629140369324161 0.22519370970447983 0.9336151752919599" />
            </geometry>
        </collision>
    </link>
    <link name="link3NPP">
        <inertial>
            <origin xyz="0 0.29350805005802866 0" rpy="0 0 0"/>
            <mass value="1" />
            <inertia ixx="100" ixy="0" ixz="0" iyy="100" iyz="0" izz="100" />
        </inertial>
        <visual>
            <origin xyz="0 0.29350805005802866 0" rpy="0 0 0"/>
            <geometry>
                <box size="0.3908927428921762 0.5870161001160573 0.8425435754238961" />
            </geometry>
            <material name="Green">
                <color rgba="0 1 0 1"/>
            </material>
        </visual>
        <collision>
            <origin xyz="0 0.29350805005802866 0" rpy="0 0 0"/>
            <geometry>
                <box size="0.3908927428921762 0.5870161001160573 0.8425435754238961" />
            </geometry>
        </collision>
    </link>
    <link name="link4NPP">
        <inertial>
            <origin xyz="0 0 0.45003491493445824" rpy="0 0 0"/>
            <mass value="1" />
            <inertia ixx="100" ixy="0" ixz="0" iyy="100" iyz="0" izz="100" />
        </inertial>
        <visual>
            <origin xyz="0 0 0.45003491493445824" rpy="0 0 0"/>
            <geometry>
                <box size="0.2729727630641807 0.5972886214257913 0.9000698298689165" />
            </geometry>
            <material name="Green">
                <color rgba="0 1 0 1"/>
            </material>
        </visual>
        <collision>
            <origin xyz="0 0 0.45003491493445824" rpy="0 0 0"/>
            <geometry>
                <box size="0.2729727630641807 0.5972886214257913 0.9000698298689165" />
            </geometry>
        </collision>
    </link>
    <link name="link5NPP">
        <inertial>
            <origin xyz="0 0.21025344921811023 0" rpy="0 0 0"/>
            <mass value="1" />
            <inertia ixx="100" ixy="0" ixz="0" iyy="100" iyz="0" izz="100" />
        </inertial>
        <visual>
            <origin xyz="0 0.21025344921811023 0" rpy="0 0 0"/>
            <geometry>
                <box size="0.28724627674488296 0.42050689843622047 0.7652491278935118" />
            </geometry>
            <material name="Blue">
                <color rgba="0 0 1 1"/>
            </material>
        </visual>
        <collision>
            <origin xyz="0 0.21025344921811023 0" rpy="0 0 0"/>
            <geometry>
                <box size="0.28724627674488296 0.42050689843622047 0.7652491278935118" />
            </geometry>
        </collision>
    </link>
    <link name="link6NPP">
        <inertial>
            <origin xyz="0 0 0.4855354183895204" rpy="0 0 0"/>
            <mass value="1" />
            <inertia ixx="100" ixy="0" ixz="0" iyy="100" iyz="0" izz="100" />
        </inertial>
        <visual>
            <origin xyz="0 0 0.4855354183895204" rpy="0 0 0"/>
            <geometry>
                <box size="0.8515734906330688 0.41611344278812956 0.9710708367790408" />
            </geometry>
            <material name="Green">
                <color rgba="0 1 0 1"/>
            </material>
        </visual>
        <collision>
            <origin xyz="0 0 0.4855354183895204" rpy="0 0 0"/>
            <geometry>
                <box size="0.8515734906330688 0.41611344278812956 0.9710708367790408" />
            </geometry>
        </collision>
    </link>
    <link name="link1NNP">
        <inertial>
            <origin xyz="0 1 1" rpy="0 0 0"/>
            <mass value="1" />
            <inertia ixx="100" ixy="0" ixz="0" iyy="100" iyz="0" izz="100" />
        </inertial>
        <visual>
            <origin xyz="0 1 1" rpy="0 0 0"/>
            <geometry>
                <box size="0 0 1" />
            </geometry>
            <material name="Blue">
                <color rgba="0 0 1 1"/>
            </material>
        </visual>
        <collision>
            <origin xyz="0 1 1" rpy="0 0 0"/>
            <geometry>
                <box size="0 0 1" />
            </geometry>
        </collision>
    </link>
    <link name="link2NNP">
        <inertial>
            <origin xyz="-0.38145701846620805 0 0" rpy="0 0 0"/>
            <mass value="1" />
            <inertia ixx="100" ixy="0" ixz="0" iyy="100" iyz="0" izz="100" />
        </inertial>
        <visual>
            <origin xyz="-0.38145701846620805 0 0" rpy="0 0 0"/>
            <geometry>
                <box size="0.7629140369324161 0.22519370970447983 0.9336151752919599" />
            </geometry>
            <material name="Green">
                <color rgba="0 1 0 1"/>
            </material>
        </visual>
        <collision>
            <origin xyz="-0.38145701846620805 0 0" rpy="0 0 0"/>
            <geometry>
                <box size="0.7629140369324161 0.22519370970447983 0.9336151752919599" />
            </geometry>
        </collision>
    </link>
    <link name="link3NNP">
        <inertial>
            <origin xyz="0 -0.29350805005802866 0" rpy="0 0 0"/>
            <mass value="1" />
            <inertia ixx="100" ixy="0" ixz="0" iyy="100" iyz="0" izz="100" />
        </inertial>
        <visual>
            <origin xyz="0 -0.29350805005802866 0" rpy="0 0 0"/>
            <geometry>
                <box size="0.3908927428921762 0.5870161001160573 0.8425435754238961" />
            </geometry>
            <material name="Green">
                <color rgba="0 1 0 1"/>
            </material>
        </visual>
        <collision>
            <origin xyz="0 -0.29350805005802866 0" rpy="0 0 0"/>
            <geometry>
                <box size="0.3908927428921762 0.5870161001160573 0.8425435754238961" />
            </geometry>
        </collision>
    </link>
    <link name="link4NNP">
        <inertial>
            <origin xyz="0 0 0.45003491493445824" rpy="0 0 0"/>
            <mass value="1" />
            <inertia ixx="100" ixy="0" ixz="0" iyy="100" iyz="0" izz="100" />
        </inertial>
        <visual>
            <origin xyz="0 0 0.45003491493445824" rpy="0 0 0"/>
            <geometry>
                <box size="0.2729727630641807 0.5972886214257913 0.9000698298689165" />
            </geometry>
            <material name="Green">
                <color rgba="0 1 0 1"/>
            </material>
        </visual>
        <collision>
            <origin xyz="0 0 0.45003491493445824" rpy="0 0 0"/>
            <geometry>
                <box size="0.2729727630641807 0.5972886214257913 0.9000698298689165" />
            </geometry>
        </collision>
    </link>
    <link name="link5NNP">
        <inertial>
            <origin xyz="0 -0.21025344921811023 0" rpy="0 0 0"/>
            <mass value="1" />
            <inertia ixx="100" ixy="0" ixz="0" iyy="100" iyz="0" izz="100" />
        </inertial>
        <visual>
            <origin xyz="0 -0.21025344921811023 0" rpy="0 0 0"/>
            <geometry>
                <box size="0.28724627674488296 0.42050689843622047 0.7652491278935118" />
            </geometry>
            <material name="Blue">
                <color rgba="0 0 1 1"/>
            </material>
        </visual>
        <collision>
            <origin xyz="0 -0.21025344921811023 0" rpy="0 0 0"/>
            <geometry>
                <box size="0.28724627674488296 0.42050689843622047 0.7652491278935118" />
            </geometry>
        </collision>
    </link>
    <link name="link6NNP">
        <inertial>
            <origin xyz="0 0 0.4855354183895204" rpy="0 0 0"/>
            <mass value="1" />
            <inertia ixx="100" ixy="0" ixz="0" iyy="100" iyz="0" izz="100" />
        </inertial>
        <visual>
            <origin xyz="0 0 0.4855354183895204" rpy="0 0 0"/>
            <geometry>
                <box size="0.8515734906330688 0.41611344278812956 0.9710708367790408" />
            </geometry>
            <material name="Green">
                <color rgba="0 1 0 1"/>
            </material>
        </visual>
        <collision>
            <origin xyz="0 0 0.4855354183895204" rpy="0 0 0"/>
            <geometry>
                <box size="0.8515734906330688 0.41611344278812956 0.9710708367790408" />
            </geometry>
        </collision>
    </link>
    <joint name="link1NPP_link2NPP" type="revolute">
       <parent link="link1NPP"/>
       <child  link="link2NPP"/>
       <origin rpy="0 0 0" xyz="0.0 0 0.5" />
       <axis xyz="0 1 0"/>
       <limit effort="0.0" lower="-3.14159" upper="3.14159" velocity="0.0"/>
    </joint>
    <joint name="link2NPP_link3NPP" type="revolute">
       <parent link="link2NPP"/>
       <child  link="link3NPP"/>
       <origin rpy="0 0 0" xyz="-0.38145701846620805 0.11259685485223991 0" />
       <axis xyz="1 0 0"/>
       <limit effort="0.0" lower="-3.14159" upper="3.14159" velocity="0.0"/>
    </joint>
    <joint name="link3NPP_link4NPP" type="revolute">
       <parent link="link3NPP"/>
       <child  link="link4NPP"/>
       <origin rpy="0 0 0" xyz="0 0.29350805005802866 0.42127178771194806" />
       <axis xyz="1 0 0"/>
       <limit effort="0.0" lower="-3.14159" upper="3.14159" velocity="0.0"/>
    </joint>
    <joint name="link4NPP_link5NPP" type="revolute">
       <parent link="link4NPP"/>
       <child  link="link5NPP"/>
       <origin rpy="0 0 0" xyz="0 0.29864431071289566 0.45003491493445824" />
       <axis xyz="1 0 0"/>
       <limit effort="0.0" lower="-3.14159" upper="3.14159" velocity="0.0"/>
    </joint>
    <joint name="link5NPP_link6NPP" type="revolute">
       <parent link="link5NPP"/>
       <child  link="link6NPP"/>
       <origin rpy="0 0 0" xyz="0 0.21025344921811023 0.3826245639467559" />
       <axis xyz="1 0 0"/>
       <limit effort="0.0" lower="-3.14159" upper="3.14159" velocity="0.0"/>
    </joint>
    <joint name="link1NNP_link2NNP" type="revolute">
       <parent link="link1NNP"/>
       <child  link="link2NNP"/>
       <origin rpy="0 0 0" xyz="0.0 0 0.5" />
       <axis xyz="0 1 0"/>
       <limit effort="0.0" lower="-3.14159" upper="3.14159" velocity="0.0"/>
    </joint>
    <joint name="link2NNP_link3NNP" type="revolute">
       <parent link="link2NNP"/>
       <child  link="link3NNP"/>
       <origin rpy="0 0 0" xyz="-0.38145701846620805 -0.11259685485223991 0" />
       <axis xyz="1 0 0"/>
       <limit effort="0.0" lower="-3.14159" upper="3.14159" velocity="0.0"/>
    </joint>
    <joint name="link3NNP_link4NNP" type="revolute">
       <parent link="link3NNP"/>
       <child  link="link4NNP"/>
       <origin rpy="0 0 0" xyz="0 -0.29350805005802866 0.42127178771194806" />
       <axis xyz="1 0 0"/>
       <limit effort="0.0" lower="-3.14159" upper="3.14159" velocity="0.0"/>
    </joint>
    <joint name="link4NNP_link5NNP" type="revolute">
       <parent link="link4NNP"/>
       <child  link="link5NNP"/>
       <origin rpy="0 0 0" xyz="0 -0.29864431071289566 0.45003491493445824" />
       <axis xyz="1 0 0"/>
       <limit effort="0.0" lower="-3.14159" upper="3.14159" velocity="0.0"/>
    </joint>
    <joint name="link5NNP_link6NNP" type="revolute">
       <parent link="link5NNP"/>
       <child  link="link6NNP"/>
       <origin rpy="0 0 0" xyz="0 -0.21025344921811023 0.3826245639467559" />
       <axis xyz="1 0 0"/>
       <limit effort="0.0" lower="-3.14159" upper="3.14159" velocity="0.0"/>
    </joint>
</robot>