<robot name = "robot">
    <link name="link1">
        <inertial>
            <origin xyz="0.6207815960426794 0 2.1489956363438445" rpy="0 0 0"/>
            <mass value="1.5423794864957996" />
            <inertia ixx="100" ixy="0" ixz="0" iyy="100" iyz="0" izz="100" />
        </inertial>
        <visual>
            <origin xyz="0.6207815960426794 0 2.1489956363438445" rpy="0 0 0"/>
            <geometry>
                <box size="1.2415631920853587 2.3956212505253918 2.1489956363438445" />
            </geometry>
            <material name="Blue">
                <color rgba="0 0 1 1"/>
            </material>
        </visual>
        <collision>
            <origin xyz="0.6207815960426794 0 2.1489956363438445" rpy="0 0 0"/>
            <geometry>
                <box size="1.2415631920853587 2.3956212505253918 2.1489956363438445" />
            </geometry>
        </collision>
    </link>
    <joint name="link1_link2" type="revolute">
       <parent link="link1"/>
       <child  link="link2"/>
       <origin rpy="0 0 0" xyz="1.2415631920853587 0 2.1489956363438445" />
       <axis xyz="0 1 0"/>
       <limit effort="0.0" lower="-3.14159" upper="3.14159" velocity="0.0"/>
    </joint>
    <link name="link2">
        <inertial>
            <origin xyz="0.6504146198458015 0 0" rpy="0 0 0"/>
            <mass value="4.970383719628497" />
            <inertia ixx="100" ixy="0" ixz="0" iyy="100" iyz="0" izz="100" />
        </inertial>
        <visual>
            <origin xyz="0.6504146198458015 0 0" rpy="0 0 0"/>
            <geometry>
                <box size="1.300829239691603 1.7550474037644168 1.539554337202965" />
            </geometry>
            <material name="Blue">
                <color rgba="0 0 1 1"/>
            </material>
        </visual>
        <collision>
            <origin xyz="0.6504146198458015 0 0" rpy="0 0 0"/>
            <geometry>
                <box size="1.300829239691603 1.7550474037644168 1.539554337202965" />
            </geometry>
        </collision>
    </link>
    <joint name="link2_link3" type="revolute">
       <parent link="link2"/>
       <child  link="link3"/>
       <origin rpy="0 0 0" xyz="1.300829239691603 0 0" />
       <axis xyz="0 1 0"/>
       <limit effort="0.0" lower="-3.14159" upper="3.14159" velocity="0.0"/>
    </joint>
    <link name="link3">
        <inertial>
            <origin xyz="0.8153902406683762 0 0" rpy="0 0 0"/>
            <mass value="2.523718376968817" />
            <inertia ixx="100" ixy="0" ixz="0" iyy="100" iyz="0" izz="100" />
        </inertial>
        <visual>
            <origin xyz="0.8153902406683762 0 0" rpy="0 0 0"/>
            <geometry>
                <box size="1.6307804813367524 1.0166957947158788 1.7181869538334105" />
            </geometry>
            <material name="Blue">
                <color rgba="0 0 1 1"/>
            </material>
        </visual>
        <collision>
            <origin xyz="0.8153902406683762 0 0" rpy="0 0 0"/>
            <geometry>
                <box size="1.6307804813367524 1.0166957947158788 1.7181869538334105" />
            </geometry>
        </collision>
    </link>
    <joint name="link3_link4" type="revolute">
       <parent link="link3"/>
       <child  link="link4"/>
       <origin rpy="0 0 0" xyz="1.6307804813367524 0 0" />
       <axis xyz="0 1 0"/>
       <limit effort="0.0" lower="-3.14159" upper="3.14159" velocity="0.0"/>
    </joint>
    <link name="link4">
        <inertial>
            <origin xyz="0.8836024064642912 0 0" rpy="0 0 0"/>
            <mass value="4.581224946877182" />
            <inertia ixx="100" ixy="0" ixz="0" iyy="100" iyz="0" izz="100" />
        </inertial>
        <visual>
            <origin xyz="0.8836024064642912 0 0" rpy="0 0 0"/>
            <geometry>
                <box size="1.7672048129285824 1.2374422889396572 0.5792046993859503" />
            </geometry>
            <material name="Blue">
                <color rgba="0 0 1 1"/>
            </material>
        </visual>
        <collision>
            <origin xyz="0.8836024064642912 0 0" rpy="0 0 0"/>
            <geometry>
                <box size="1.7672048129285824 1.2374422889396572 0.5792046993859503" />
            </geometry>
        </collision>
    </link>
</robot>